Workbook

Sheet 使い方
A1: 就労継続支援B型 愛媛（西条市）開設シミュレーション
A2: クロスボーダーキャリアパス構想「全国にトータルサポートを。」の第一歩として、放課後等デイサービス卒業後の受け皿となるB型事業所を愛媛で開設した場合の収支を試算します。
A4: ■ シートの構成
A5: 前提条件：すべての入力値。青字・黄色セルを変えると全シートが再計算されます。シナリオ（慎重／標準／積極）はここで切り替えます。
A6: 月次シミュレーション：開設前＋36か月の利用者数・給付費・費用・営業利益・資金残高（国保連入金は2か月遅れ）。
A7: 年次サマリー：1〜3年目の損益、単月黒字化月、投資回収月。
A8: 感度分析：平均利用者数と基本報酬区分（平均工賃月額）を変えた場合の安定期の年間営業利益。
A9: 開設ロードマップ：開設までの準備工程と、キャレオス内の連携先。
A11: ■ セルの色分け
A12: 青字＋黄色塗り＝入力する前提値（ここだけ変更してください） ／ 黒字＝計算式 ／ 緑字＝他シートからの参照
A14: ■ 制度面の前提と出典（必ず最新の告示・愛媛県／西条市の確認を）
A15: ・基本報酬：就労継続支援B型サービス費（Ⅰ）人員配置6:1・定員20人以下。単位数は令和6年度改定の値（837/805/758/738/726/703/673/590単位）。
... A25: 出典：藤原行政書士事務所「令和8年6月施行『新規指定事業所の基本報酬引き下げ』」 https://fujiwaragyoseishoshi.com/kaitei20260522/

Sheet 前提条件
A1: 前提条件（入力シート）
A2: 青字・黄色のセルが入力値です。
A3: 項目 | B3: 値 | C3: 単位 | D3: 根拠・メモ
A4: ■ シナリオ
A5: 採用シナリオ | B5: 標準 | D5: 「慎重」「標準」「積極」から選択（下のシナリオ表を参照）
A6: ■ 事業所の基本
A7: 開設月 | B7: =DATE(2027,4,1) -> 46478 | D7: 指定申請・物件・採用に約6か月かかる想定で2027年4月開設
A8: 利用定員 | B8: 20 | C8: 人 | D8: 定員20人以下の報酬区分
A9: 月の開所日数 | B9: 22 | C9: 日 | D9: 平日開所（原則の日数）
A10: 1単位の単価 | B10: 10 | C10: 円 | D10: 地域区分「その他」を仮定（西条市、要確認）
A11: ■ 報酬（1人1日あたり）
A12: 1年目の基本報酬単位 | B12: 673 | C12: 単位 | D12: 新規指定の初年度は「1万円以上1.5万円未満」区分と仮定（要確認）
A13: 新規指定事業所の特例 | B13: 0.984 | C13: 倍 | D13: 令和8年6月以降の新規指定：所定単位数×984/1000
A14: 送迎加算（片道） | B14: 21 | C14: 単位 | D14: 送迎加算（Ⅰ）を仮定
A15: 送迎の利用率 | B15: 0.7 | D15: 利用者のうち送迎を使う割合（往復）
A16: 食事提供体制加算 | B16: 30 | C16: 単位 | D16: 令和9年3月までの経過措置の想定（要確認）
A17: 食事提供の対象率 | B17: 0.5 | D17: 低所得等で対象となる利用者の割合
A18: 福祉専門職員配置等加算 | B18: 6 | C18: 単位 | D18: （Ⅲ）を仮定
A19: 処遇改善加算の率 | B19: 0.093 | D19: （Ⅰ）9.3%を仮定。全額を賃金改善に充当
A20: ■ 人件費（月額）
A21: 管理者 兼 サービス管理責任者 給与 | B21: 320000 | C21: 円 | D21: 仮置き。本人が管理者を担う想定
A22: 職業指導員・生活支援員 給与（常勤1人） | B22: 230000 | C22: 円 | D22: 仮置き（愛媛の相場を要確認）
A23: 人員配置（利用者：職員） | B23: 6 | C23: 人 | D23: サービス費（Ⅰ）6:1
A24: 支援員の最低人数（常勤換算） | B24: 2 | C24: 人 | D24: 立ち上げ期も最低2人は配置
A25: 賞与（年間の月数） | B25: 2 | C25: か月 | D25: 月額に按分して計上
A26: 法定福利費率 | B26: 0.15 | D26: 社会保険料の会社負担
A27: 送迎ドライバー（パート） | B27: 80000 | C27: 円 | D27: 仮置き
A28: ■ その他の費用（月額）
A29: 家賃 | B29: 120000 | C29: 円 | D29: 西条市内・約50坪を仮定
A30: 車両リース（2台） | B30: 70000 | C30: 円 | D30: 送迎車2台
A31: 水道光熱・通信・システム | B31: 70000 | C31: 円 | D31: 請求ソフト含む
A32: 保険・広報・雑費 | B32: 50000 | C32: 円
A33: 変動費（利用1人1日あたり） | B33: 200 | C33: 円 | D33: 消耗品・食材差額など
A34: 本部費（給付費に対する率） | B34: 0.03 | D34: 法人本部への配賦を仮定
A35: ■ 初期投資
A36: 内装・設備工事 | B36: 5000000 | C36: 円 | D36: 10年で償却
A37: 備品・作業機器 | B37: 1500000 | C37: 円 | D37: 5年で償却
A38: 開設準備費（開設前の人件費・研修・広告） | B38: 2000000 | C38: 円 | D38: 開設月の前に一括計上
A39: 敷金・保証金 | B39: 500000 | C39: 円 | D39: 資産（費用にしない）
A40: 国保連からの入金の遅れ | B40: 2 | C40: か月 | D40: サービス提供月の翌々月に入金
...

Sheet 月次シミュレーション
A1: 月次シミュレーション（金額：円）
A2: =CONCATENATE("シナリオ：",前提条件!$B$5) -> シナリオ：標準
A4: 月番号 | B4: 年月 | C4: 年次 | D4: 平均利用者数/日 | E4: 延べ利用（人日） | F4: 平均工賃月額 | G4: 基本報酬単位 | H4: 基本報酬 | I4: 加算 | J4: 処遇改善加算 | K4: 給付費 合計 | L4: 支援員（常勤換算） | M4: 人件費 | N4: 処遇改善分の賃金 | O4: 家賃・車両・光熱等 | P4: 変動費 | Q4: 本部費 | R4: 減価償却 | S4: 費用 合計 | T4: 営業利益 | U4: 累積営業利益 | V4: 入金（国保連） | W4: 出金（償却除く） | X4: 月次収支 | Y4: 資金残高 | Z4: 黒字月 | AA4: 回収月
A5: 0 | B5: 開設前 | C5: 0 | D5: 0 | E5: 0 | F5: 0 | G5: 0 | H5: 0 | I5: 0 | J5: 0 | K5: 0 | L5: 0 | M5: 0 | N5: 0 | O5: 0 | P5: 0 | Q5: 0 | R5: 0 | S5: =前提条件!$B$38 -> 2000000 | T5: =-S5 -> -2000000 | U5: =T5 -> -2000000 | V5: 0 | W5: =前提条件!$B$38+前提条件!$B$36+前提条件!$B$37+前提条件!$B$39 -> 9000000 | X5: =-W5 -> -9000000 | Y5: =X5 -> -9000000 | Z5: 0 | AA5: 0
A6: 1 | B6: =EDATE(前提条件!$B$7,A6-1) -> 46478 | C6: =INT((A6-1)/12)+1 -> 1 | D6: =MIN(前提条件!$B$8*前提条件!$E$46,前提条件!$E$44+(A6-1)*前提条件!$E$45) -> 5 | E6: =D6*前提条件!$B$9 -> 110 | F6: =IF(C6=1,"初年度",IF(C6=2,前提条件!$E$47,前提条件!$E$48)) -> 初年度 | G6: =IF(C6=1,前提条件!$B$12,INDEX(前提条件!$C$52:$C$59,MATCH(F6,前提条件!$B$52:$B$59,1))) -> 673 | H6: =E6*G6*前提条件!$B$13*前提条件!$B$10 -> 728455.2 | I6: =E6*(前提条件!$B$14*2*前提条件!$B$15+前提条件!$B$16*前提条件!$B$17+前提条件!$B$18)*前提条件!$B$10 -> 55440 | J6: =(H6+I6)*前提条件!$B$19 -> 72902.254 | K6: =H6+I6+J6 -> 856797.45 | L6: =MAX(前提条件!$B$24,CEILING(D6/前提条件!$B$23,0.5)) -> 2 | M6: =(前提条件!$B$21+L6*前提条件!$B$22)*(12+前提条件!$B$25)/12*(1+前提条件!$B$26)+前提条件!$B$27 -> 1126500 | N6: =J6 -> 72902.254 | O6: =前提条件!$B$29+前提条件!$B$30+前提条件!$B$31+前提条件!$B$32 -> 310000 | P6: =E6*前提条件!$B$33 -> 22000 | Q6: =K6*前提条件!$B$34 -> 25703.924 | R6: =前提条件!$B$36/120+前提条件!$B$37/60 -> 66666.667 | S6: =SUM(M6:R6) -> 1623772.8 | T6: =K6-S6 -> -766975.39 | U6: =U5+T6 -> -2766975.4 | V6: =IF(A6>前提条件!$B$40,OFFSET(K6,-前提条件!$B$40,0),0) -> 0 | W6: =S6-R6 -> 1557106.2 | X6: =V6-W6 -> -1557106.2 | Y6: =Y5+X6 -> -10557106 | Z6: =IF(T6>0,1,0) -> 0 | AA6: =IF(Y6>=0,1,0) -> 0
A7: 2 | B7: =EDATE(前提条件!$B$7,A7-1) -> 46508 | C7: =INT((A7-1)/12)+1 -> 1 | D7: =MIN(前提条件!$B$8*前提条件!$E$46,前提条件!$E$44+(A7-1)*前提条件!$E$45) -> 6.2 | E7: =D7*前提条件!$B$9 -> 136.4 | F7: =IF(C7=1,"初年度",IF(C7=2,前提条件!$E$47,前提条件!$E$48)) -> 初年度 | G7: =IF(C7=1,前提条件!$B$12,INDEX(前提条件!$C$52:$C$59,MATCH(F7,前提条件!$B$52:$B$59,1))) -> 673 | H7: =E7*G7*前提条件!$B$13*前提条件!$B$10 -> 903284.45 | I7: =E7*(前提条件!$B$14*2*前提条件!$B$15+前提条件!$B$16*前提条件!$B$17+前提条件!$B$18)*前提条件!$B$10 -> 68745.6 | J7: =(H7+I7)*前提条件!$B$19 -> 90398.794 | K7: =H7+I7+J7 -> 1062428.8 | L7: =MAX(前提条件!$B$24,CEILING(D7/前提条件!$B$23,0.5)) -> 2 | M7: =(前提条件!$B$21+L7*前提条件!$B$22)*(12+前提条件!$B$25)/12*(1+前提条件!$B$26)+前提条件!$B$27 -> 1126500 | N7: =J7 -> 90398.794 | O7: =前提条件!$B$29+前提条件!$B$30+前提条件!$B$31+前提条件!$B$32 -> 310000 | P7: =E7*前提条件!$B$33 -> 27280 | Q7: =K7*前提条件!$B$34 -> 31872.865 | R7: =前提条件!$B$36/120+前提条件!$B$37/60 -> 66666.667 | S7: =SUM(M7:R7) -> 1652718.3 | T7: =K7-S7 -> -590289.48 | U7: =U6+T7 -> -3357264.9 | V7: =IF(A7>前提条件!$B$40,OFFSET(K7,-前提条件!$B$40,0),0) -> 0 | W7: =S7-R7 -> 1586051.7 | X7: =V7-W7 -> -1586051.7 | Y7: =Y6+X7 -> -12143158 | Z7: =IF(T7>0,1,0) -> 0 | AA7: =IF(Y7>=0,1,0) -> 0
A8: 3 | B8: =EDATE(前提条件!$B$7,A8-1) -> 46539 | C8: =INT((A8-1)/12)+1 -> 1 | D8: =MIN(前提条件!$B$8*前提条件!$E$46,前提条件!$E$44+(A8-1)*前提条件!$E$45) -> 7.4 | E8: =D8*前提条件!$B$9 -> 162.8 | F8: =IF(C8=1,"初年度",IF(C8=2,前提条件!$E$47,前提条件!$E$48)) -> 初年度 | G8: =IF(C8=1,前提条件!$B$12,INDEX(前提条件!$C$52:$C$59,MATCH(F8,前提条件!$B$52:$B$59,1))) -> 673 | H8: =E8*G8*前提条件!$B$13*前提条件!$B$10 -> 1078113.7 | I8: =E8*(前提条件!$B$14*2*前提条件!$B$15+前提条件!$B$16*前提条件!$B$17+前提条件!$B$18)*前提条件!$B$10 -> 82051.2 | J8: =(H8+I8)*前提条件!$B$19 -> 107895.34 | K8: =H8+I8+J8 -> 1268060.2 | L8: =MAX(前提条件!$B$24,CEILING(D8/前提条件!$B$23,0.5)) -> 2 | M8: =(前提条件!$B$21+L8*前提条件!$B$22)*(12+前提条件!$B$25)/12*(1+前提条件!$B$26)+前提条件!$B$27 -> 1126500 | N8: =J8 -> 107895.34 | O8: =前提条件!$B$29+前提条件!$B$30+前提条件!$B$31+前提条件!$B$32 -> 310000 | P8: =E8*前提条件!$B$33 -> 32560 | Q8: =K8*前提条件!$B$34 -> 38041.807 | R8: =前提条件!$B$36/120+前提条件!$B$37/60 -> 66666.667 | S8: =SUM(M8:R8) -> 1681663.8 | T8: =K8-S8 -> -413603.58 | U8: =U7+T8 -> -3770868.5 | V8: =IF(A8>前提条件!$B$40,OFFSET(K8,-前提条件!$B$40,0),0) -> 856797.45 | W8: =S8-R8 -> 1614997.1 | X8: =V8-W8 -> -758199.69 | Y8: =Y7+X8 -> -12901358 | Z8: =IF(T8>0,1,0) -> 0 | AA8: =IF(Y8>=0,1,0) -> 0
A9: 4 | B9: =EDATE(前提条件!$B$7,A9-1) -> 46569 | C9: =INT((A9-1)/12)+1 -> 1 | D9: =MIN(前提条件!$B$8*前提条件!$E$46,前提条件!$E$44+(A9-1)*前提条件!$E$45) -> 8.6 | E9: =D9*前提条件!$B$9 -> 189.2 | F9: =IF(C9=1,"初年度",IF(C9=2,前提条件!$E$47,前提条件!$E$48)) -> 初年度 | G9: =IF(C9=1,前提条件!$B$12,INDEX(前提条件!$C$52:$C$59,MATCH(F9,前提条件!$B$52:$B$59,1))) -> 673 | H9: =E9*G9*前提条件!$B$13*前提条件!$B$10 -> 1252942.9 | I9: =E9*(前提条件!$B$14*2*前提条件!$B$15+前提条件!$B$16*前提条件!$B$17+前提条件!$B$18)*前提条件!$B$10 -> 95356.8 | J9: =(H9+I9)*前提条件!$B$19 -> 125391.88 | K9: =H9+I9+J9 -> 1473691.6 | L9: =MAX(前提条件!$B$24,CEILING(D9/前提条件!$B$23,0.5)) -> 2 | M9: =(前提条件!$B$21+L9*前提条件!$B$22)*(12+前提条件!$B$25)/12*(1+前提条件!$B$26)+前提条件!$B$27 -> 1126500 | N9: =J9 -> 125391.88 | O9: =前提条件!$B$29+前提条件!$B$30+前提条件!$B$31+前提条件!$B$32 -> 310000 | P9: =E9*前提条件!$B$33 -> 37840 | Q9: =K9*前提条件!$B$34 -> 44210.749 | R9: =前提条件!$B$36/120+前提条件!$B$37/60 -> 66666.667 | S9: =SUM(M9:R9) -> 1710609.3 | T9: =K9-S9 -> -236917.67 | U9: =U8+T9 -> -4007786.1 | V9: =IF(A9>前提条件!$B$40,OFFSET(K9,-前提条件!$B$40,0),0) -> 1062428.8 | W9: =S9-R9 -> 1643942.6 | X9: =V9-W9 -> -581513.78 | Y9: =Y8+X9 -> -13482871 | Z9: =IF(T9>0,1,0) -> 0 | AA9: =IF(Y9>=0,1,0) -> 0
A10: 5 | B10: =EDATE(前提条件!$B$7,A10-1) -> 46600 | C10: =INT((A10-1)/12)+1 -> 1 | D10: =MIN(前提条件!$B$8*前提条件!$E$46,前提条件!$E$44+(A10-1)*前提条件!$E$45) -> 9.8 | E10: =D10*前提条件!$B$9 -> 215.6 | F10: =IF(C10=1,"初年度",IF(C10=2,前提条件!$E$47,前提条件!$E$48)) -> 初年度 | G10: =IF(C10=1,前提条件!$B$12,INDEX(前提条件!$C$52:$C$59,MATCH(F10,前提条件!$B$52:$B$59,1))) -> 673 | H10: =E10*G10*前提条件!$B$13*前提条件!$B$10 -> 1427772.2 | I10: =E10*(前提条件!$B$14*2*前提条件!$B$15+前提条件!$B$16*前提条件!$B$17+前提条件!$B$18)*前提条件!$B$10 -> 108662.4 | J10: =(H10+I10)*前提条件!$B$19 -> 142888.42 | K10: =H10+I10+J10 -> 1679323 | L10: =MAX(前提条件!$B$24,CEILING(D10/前提条件!$B$23,0.5)) -> 2 | M10: =(前提条件!$B$21+L10*前提条件!$B$22)*(12+前提条件!$B$25)/12*(1+前提条件!$B$26)+前提条件!$B$27 -> 1126500 | N10: =J10 -> 142888.42 | O10: =前提条件!$B$29+前提条件!$B$30+前提条件!$B$31+前提条件!$B$32 -> 310000 | P10: =E10*前提条件!$B$33 -> 43120 | Q10: =K10*前提条件!$B$34 -> 50379.69 | R10: =前提条件!$B$36/120+前提条件!$B$37/60 -> 66666.667 | S10: =SUM(M10:R10) -> 1739554.8 | T10: =K10-S10 -> -60231.765 | U10: =U9+T10 -> -4068017.9 | V10: =IF(A10>前提条件!$B$40,OFFSET(K10,-前提条件!$B$40,0),0) -> 1268060.2 | W10: =S10-R10 -> 1672888.1 | X10: =V10-W10 -> -404827.88 | Y10: =Y9+X10 -> -13887699 | Z10: =IF(T10>0,1,0) -> 0 | AA10: =IF(Y10>=0,1,0) -> 0
A11: 6 | B11: =EDATE(前提条件!$B$7,A11-1) -> 46631 | C11: =INT((A11-1)/12)+1 -> 1 | D11: =MIN(前提条件!$B$8*前提条件!$E$46,前提条件!$E$44+(A11-1)*前提条件!$E$45) -> 11 | E11: =D11*前提条件!$B$9 -> 242 | F11: =IF(C11=1,"初年度",IF(C11=2,前提条件!$E$47,前提条件!$E$48)) -> 初年度 | G11: =IF(C11=1,前提条件!$B$12,INDEX(前提条件!$C$52:$C$59,MATCH(F11,前提条件!$B$52:$B$59,1))) -> 673 | H11: =E11*G11*前提条件!$B$13*前提条件!$B$10 -> 1602601.4 | I11: =E11*(前提条件!$B$14*2*前提条件!$B$15+前提条件!$B$16*前提条件!$B$17+前提条件!$B$18)*前提条件!$B$10 -> 121968 | J11: =(H11+I11)*前提条件!$B$19 -> 160384.96 | K11: =H11+I11+J11 -> 1884954.4 | L11: =MAX(前提条件!$B$24,CEILING(D11/前提条件!$B$23,0.5)) -> 2 | M11: =(前提条件!$B$21+L11*前提条件!$B$22)*(12+前提条件!$B$25)/12*(1+前提条件!$B$26)+前提条件!$B$27 -> 1126500 | N11: =J11 -> 160384.96 | O11: =前提条件!$B$29+前提条件!$B$30+前提条件!$B$31+前提条件!$B$32 -> 310000 | P11: =E11*前提条件!$B$33 -> 48400 | Q11: =K11*前提条件!$B$34 -> 56548.632 | R11: =前提条件!$B$36/120+前提条件!$B$37/60 -> 66666.667 | S11: =SUM(M11:R11) -> 1768500.3 | T11: =K11-S11 -> 116454.14 | U11: =U10+T11 -> -3951563.7 | V11: =IF(A11>前提条件!$B$40,OFFSET(K11,-前提条件!$B$40,0),0) -> 1473691.6 | W11: =S11-R11 -> 1701833.6 | X11: =V11-W11 -> -228141.97 | Y11: =Y10+X11 -> -14115841 | Z11: =IF(T11>0,1,0) -> 1 | AA11: =IF(Y11>=0,1,0) -> 0
A12: 7 | B12: =EDATE(前提条件!$B$7,A12-1) -> 46661 | C12: =INT((A12-1)/12)+1 -> 1 | D12: =MIN(前提条件!$B$8*前提条件!$E$46,前提条件!$E$44+(A12-1)*前提条件!$E$45) -> 12.2 | E12: =D12*前提条件!$B$9 -> 268.4 | F12: =IF(C12=1,"初年度",IF(C12=2,前提条件!$E$47,前提条件!$E$48)) -> 初年度 | G12: =IF(C12=1,前提条件!$B$12,INDEX(前提条件!$C$52:$C$59,MATCH(F12,前提条件!$B$52:$B$59,1))) -> 673 | H12: =E12*G12*前提条件!$B$13*前提条件!$B$10 -> 1777430.7 | I12: =E12*(前提条件!$B$14*2*前提条件!$B$15+前提条件!$B$16*前提条件!$B$17+前提条件!$B$18)*前提条件!$B$10 -> 135273.6 | J12: =(H12+I12)*前提条件!$B$19 -> 177881.5 | K12: =H12+I12+J12 -> 2090585.8 | L12: =MAX(前提条件!$B$24,CEILING(D12/前提条件!$B$23,0.5)) -> 2.5 | M12: =(前提条件!$B$21+L12*前提条件!$B$22)*(12+前提条件!$B$25)/12*(1+前提条件!$B$26)+前提条件!$B$27 -> 1280791.7 | N12: =J12 -> 177881.5 | O12: =前提条件!$B$29+前提条件!$B$30+前提条件!$B$31+前提条件!$B$32 -> 310000 | P12: =E12*前提条件!$B$33 -> 53680 | Q12: =K12*前提条件!$B$34 -> 62717.574 | R12: =前提条件!$B$36/120+前提条件!$B$37/60 -> 66666.667 | S12: =SUM(M12:R12) -> 1951737.4 | T12: =K12-S12 -> 138848.38 | U12: =U11+T12 -> -3812715.4 | V12: =IF(A12>前提条件!$B$40,OFFSET(K12,-前提条件!$B$40,0),0) -> 1679323 | W12: =S12-R12 -> 1885070.7 | X12: =V12-W12 -> -205747.73 | Y12: =Y11+X12 -> -14321589 | Z12: =IF(T12>0,1,0) -> 1 | AA12: =IF(Y12>=0,1,0) -> 0
A13: 8 | B13: =EDATE(前提条件!$B$7,A13-1) -> 46692 | C13: =INT((A13-1)/12)+1 -> 1 | D13: =MIN(前提条件!$B$8*前提条件!$E$46,前提条件!$E$44+(A13-1)*前提条件!$E$45) -> 13.4 | E13: =D13*前提条件!$B$9 -> 294.8 | F13: =IF(C13=1,"初年度",IF(C13=2,前提条件!$E$47,前提条件!$E$48)) -> 初年度 | G13: =IF(C13=1,前提条件!$B$12,INDEX(前提条件!$C$52:$C$59,MATCH(F13,前提条件!$B$52:$B$59,1))) -> 673 | H13: =E13*G13*前提条件!$B$13*前提条件!$B$10 -> 1952259.9 | I13: =E13*(前提条件!$B$14*2*前提条件!$B$15+前提条件!$B$16*前提条件!$B$17+前提条件!$B$18)*前提条件!$B$10 -> 148579.2 | J13: =(H13+I13)*前提条件!$B$19 -> 195378.04 | K13: =H13+I13+J13 -> 2296217.2 | L13: =MAX(前提条件!$B$24,CEILING(D13/前提条件!$B$23,0.5)) -> 2.5 | M13: =(前提条件!$B$21+L13*前提条件!$B$22)*(12+前提条件!$B$25)/12*(1+前提条件!$B$26)+前提条件!$B$27 -> 1280791.7 | N13: =J13 -> 195378.04 | O13: =前提条件!$B$29+前提条件!$B$30+前提条件!$B$31+前提条件!$B$32 -> 310000 | P13: =E13*前提条件!$B$33 -> 58960 | Q13: =K13*前提条件!$B$34 -> 68886.515 | R13: =前提条件!$B$36/120+前提条件!$B$37/60 -> 66666.667 | S13: =SUM(M13:R13) -> 1980682.9 | T13: =K13-S13 -> 315534.29 | U13: =U12+T13 -> -3497181.1 | V13: =IF(A13>前提条件!$B$40,OFFSET(K13,-前提条件!$B$40,0),0) -> 1884954.4 | W13: =S13-R13 -> 1914016.2 | X13: =V13-W13 -> -29061.824 | Y13: =Y12+X13 -> -14350651 | Z13: =IF(T13>0,1,0) -> 1 | AA13: =IF(Y13>=0,1,0) -> 0
A14: 9 | B14: =EDATE(前提条件!$B$7,A14-1) -> 46722 | C14: =INT((A14-1)/12)+1 -> 1 | D14: =MIN(前提条件!$B$8*前提条件!$E$46,前提条件!$E$44+(A14-1)*前提条件!$E$45) -> 14.6 | E14: =D14*前提条件!$B$9 -> 321.2 | F14: =IF(C14=1,"初年度",IF(C14=2,前提条件!$E$47,前提条件!$E$48)) -> 初年度 | G14: =IF(C14=1,前提条件!$B$12,INDEX(前提条件!$C$52:$C$59,MATCH(F14,前提条件!$B$52:$B$59,1))) -> 673 | H14: =E14*G14*前提条件!$B$13*前提条件!$B$10 -> 2127089.2 | I14: =E14*(前提条件!$B$14*2*前提条件!$B$15+前提条件!$B$16*前提条件!$B$17+前提条件!$B$18)*前提条件!$B$10 -> 161884.8 | J14: =(H14+I14)*前提条件!$B$19 -> 212874.58 | K14: =H14+I14+J14 -> 2501848.6 | L14: =MAX(前提条件!$B$24,CEILING(D14/前提条件!$B$23,0.5)) -> 2.5 | M14: =(前提条件!$B$21+L14*前提条件!$B$22)*(12+前提条件!$B$25)/12*(1+前提条件!$B$26)+前提条件!$B$27 -> 1280791.7 | N14: =J14 -> 212874.58 | O14: =前提条件!$B$29+前提条件!$B$30+前提条件!$B$31+前提条件!$B$32 -> 310000 | P14: =E14*前提条件!$B$33 -> 64240 | Q14: =K14*前提条件!$B$34 -> 75055.457 | R14: =前提条件!$B$36/120+前提条件!$B$37/60 -> 66666.667 | S14: =SUM(M14:R14) -> 2009628.4 | T14: =K14-S14 -> 492220.19 | U14: =U13+T14 -> -3004960.9 | V14: =IF(A14>前提条件!$B$40,OFFSET(K14,-前提条件!$B$40,0),0) -> 2090585.8 | W14: =S14-R14 -> 1942961.7 | X14: =V14-W14 -> 147624.08 | Y14: =Y13+X14 -> -14203027 | Z14: =IF(T14>0,1,0) -> 1 | AA14: =IF(Y14>=0,1,0) -> 0
A15: 10 | B15: =EDATE(前提条件!$B$7,A15-1) -> 46753 | C15: =INT((A15-1)/12)+1 -> 1 | D15: =MIN(前提条件!$B$8*前提条件!$E$46,前提条件!$E$44+(A15-1)*前提条件!$E$45) -> 15.8 | E15: =D15*前提条件!$B$9 -> 347.6 | F15: =IF(C15=1,"初年度",IF(C15=2,前提条件!$E$47,前提条件!$E$48)) -> 初年度 | G15: =IF(C15=1,前提条件!$B$12,INDEX(前提条件!$C$52:$C$59,MATCH(F15,前提条件!$B$52:$B$59,1))) -> 673 | H15: =E15*G15*前提条件!$B$13*前提条件!$B$10 -> 2301918.4 | I15: =E15*(前提条件!$B$14*2*前提条件!$B$15+前提条件!$B$16*前提条件!$B$17+前提条件!$B$18)*前提条件!$B$10 -> 175190.4 | J15: =(H15+I15)*前提条件!$B$19 -> 230371.12 | K15: =H15+I15+J15 -> 2707480 | L15: =MAX(前提条件!$B$24,CEILING(D15/前提条件!$B$23,0.5)) -> 3 | M15: =(前提条件!$B$21+L15*前提条件!$B$22)*(12+前提条件!$B$25)/12*(1+前提条件!$B$26)+前提条件!$B$27 -> 1435083.3 | N15: =J15 -> 230371.12 | O15: =前提条件!$B$29+前提条件!$B$30+前提条件!$B$31+前提条件!$B$32 -> 310000 | P15: =E15*前提条件!$B$33 -> 69520 | Q15: =K15*前提条件!$B$34 -> 81224.399 | R15: =前提条件!$B$36/120+前提条件!$B$37/60 -> 66666.667 | S15: =SUM(M15:R15) -> 2192865.5 | T15: =K15-S15 -> 514614.43 | U15: =U14+T15 -> -2490346.5 | V15: =IF(A15>前提条件!$B$40,OFFSET(K15,-前提条件!$B$40,0),0) -> 2296217.2 | W15: =S15-R15 -> 2126198.9 | X15: =V15-W15 -> 170018.32 | Y15: =Y14+X15 -> -14033008 | Z15: =IF(T15>0,1,0) -> 1 | AA15: =IF(Y15>=0,1,0) -> 0
A16: 11 | B16: =EDATE(前提条件!$B$7,A16-1) -> 46784 | C16: =INT((A16-1)/12)+1 -> 1 | D16: =MIN(前提条件!$B$8*前提条件!$E$46,前提条件!$E$44+(A16-1)*前提条件!$E$45) -> 17 | E16: =D16*前提条件!$B$9 -> 374 | F16: =IF(C16=1,"初年度",IF(C16=2,前提条件!$E$47,前提条件!$E$48)) -> 初年度 | G16: =IF(C16=1,前提条件!$B$12,INDEX(前提条件!$C$52:$C$59,MATCH(F16,前提条件!$B$52:$B$59,1))) -> 673 | H16: =E16*G16*前提条件!$B$13*前提条件!$B$10 -> 2476747.7 | I16: =E16*(前提条件!$B$14*2*前提条件!$B$15+前提条件!$B$16*前提条件!$B$17+前提条件!$B$18)*前提条件!$B$10 -> 188496 | J16: =(H16+I16)*前提条件!$B$19 -> 247867.66 | K16: =H16+I16+J16 -> 2913111.3 | L16: =MAX(前提条件!$B$24,CEILING(D16/前提条件!$B$23,0.5)) -> 3 | M16: =(前提条件!$B$21+L16*前提条件!$B$22)*(12+前提条件!$B$25)/12*(1+前提条件!$B$26)+前提条件!$B$27 -> 1435083.3 | N16: =J16 -> 247867.66 | O16: =前提条件!$B$29+前提条件!$B$30+前提条件!$B$31+前提条件!$B$32 -> 310000 | P16: =E16*前提条件!$B$33 -> 74800 | Q16: =K16*前提条件!$B$34 -> 87393.34 | R16: =前提条件!$B$36/120+前提条件!$B$37/60 -> 66666.667 | S16: =SUM(M16:R16) -> 2221811 | T16: =K16-S16 -> 691300.34 | U16: =U15+T16 -> -1799046.1 | V16: =IF(A16>前提条件!$B$40,OFFSET(K16,-前提条件!$B$40,0),0) -> 2501848.6 | W16: =S16-R16 -> 2155144.3 | X16: =V16-W16 -> 346704.23 | Y16: =Y15+X16 -> -13686304 | Z16: =IF(T16>0,1,0) -> 1 | AA16: =IF(Y16>=0,1,0) -> 0
A17: 12 | B17: =EDATE(前提条件!$B$7,A17-1) -> 46813 | C17: =INT((A17-1)/12)+1 -> 1 | D17: =MIN(前提条件!$B$8*前提条件!$E$46,前提条件!$E$44+(A17-1)*前提条件!$E$45) -> 18 | E17: =D17*前提条件!$B$9 -> 396 | F17: =IF(C17=1,"初年度",IF(C17=2,前提条件!$E$47,前提条件!$E$48)) -> 初年度 | G17: =IF(C17=1,前提条件!$B$12,INDEX(前提条件!$C$52:$C$59,MATCH(F17,前提条件!$B$52:$B$59,1))) -> 673 | H17: =E17*G17*前提条件!$B$13*前提条件!$B$10 -> 2622438.7 | I17: =E17*(前提条件!$B$14*2*前提条件!$B$15+前提条件!$B$16*前提条件!$B$17+前提条件!$B$18)*前提条件!$B$10 -> 199584 | J17: =(H17+I17)*前提条件!$B$19 -> 262448.11 | K17: =H17+I17+J17 -> 3084470.8 | L17: =MAX(前提条件!$B$24,CEILING(D17/前提条件!$B$23,0.5)) -> 3 | M17: =(前提条件!$B$21+L17*前提条件!$B$22)*(12+前提条件!$B$25)/12*(1+前提条件!$B$26)+前提条件!$B$27 -> 1435083.3 | N17: =J17 -> 262448.11 | O17: =前提条件!$B$29+前提条件!$B$30+前提条件!$B$31+前提条件!$B$32 -> 310000 | P17: =E17*前提条件!$B$33 -> 79200 | Q17: =K17*前提条件!$B$34 -> 92534.125 | R17: =前提条件!$B$36/120+前提条件!$B$37/60 -> 66666.667 | S17: =SUM(M17:R17) -> 2245932.2 | T17: =K17-S17 -> 838538.6 | U17: =U16+T17 -> -960507.52 | V17: =IF(A17>前提条件!$B$40,OFFSET(K17,-前提条件!$B$40,0),0) -> 2707480 | W17: =S17-R17 -> 2179265.6 | X17: =V17-W17 -> 528214.38 | Y17: =Y16+X17 -> -13158090 | Z17: =IF(T17>0,1,0) -> 1 | AA17: =IF(Y17>=0,1,0) -> 0
... A41: 36 | B41: =EDATE(前提条件!$B$7,A41-1) -> 47543 | C41: =INT((A41-1)/12)+1 -> 3 | D41: =MIN(前提条件!$B$8*前提条件!$E$46,前提条件!$E$44+(A41-1)*前提条件!$E$45) -> 18 | E41: =D41*前提条件!$B$9 -> 396 | F41: =IF(C41=1,"初年度",IF(C41=2,前提条件!$E$47,前提条件!$E$48)) -> 19000 | G41: =IF(C41=1,前提条件!$B$12,INDEX(前提条件!$C$52:$C$59,MATCH(F41,前提条件!$B$52:$B$59,1))) -> 703 | H41: =E41*G41*前提条件!$B$13*前提条件!$B$10 -> 2739337.9 | I41: =E41*(前提条件!$B$14*2*前提条件!$B$15+前提条件!$B$16*前提条件!$B$17+前提条件!$B$18)*前提条件!$B$10 -> 199584 | J41: =(H41+I41)*前提条件!$B$19 -> 273319.74 | K41: =H41+I41+J41 -> 3212241.7 | L41: =MAX(前提条件!$B$24,CEILING(D41/前提条件!$B$23,0.5)) -> 3 | M41: =(前提条件!$B$21+L41*前提条件!$B$22)*(12+前提条件!$B$25)/12*(1+前提条件!$B$26)+前提条件!$B$27 -> 1435083.3 | N41: =J41 -> 273319.74 | O41: =前提条件!$B$29+前提条件!$B$30+前提条件!$B$31+前提条件!$B$32 -> 310000 | P41: =E41*前提条件!$B$33 -> 79200 | Q41: =K41*前提条件!$B$34 -> 96367.25 | R41: =前提条件!$B$36/120+前提条件!$B$37/60 -> 66666.667 | S41: =SUM(M41:R41) -> 2260637 | T41: =K41-S41 -> 951604.67 | U41: =U40+T41 -> 20521212 | V41: =IF(A41>前提条件!$B$40,OFFSET(K41,-前提条件!$B$40,0),0) -> 3212241.7 | W41: =S41-R41 -> 2193970.3 | X41: =V41-W41 -> 1018271.3 | Y41: =Y40+X41 -> 9496728.3 | Z41: =IF(T41>0,1,0) -> 1 | AA41: =IF(Y41>=0,1,0) -> 1

Sheet 年次サマリー
A1: 年次サマリー（金額：円）
A2: =CONCATENATE("シナリオ：",前提条件!$B$5) -> シナリオ：標準
A4: 項目 | B4: 開設前 | C4: 1年目 | D4: 2年目 | E4: 3年目 | F4: 3年間 合計
A5: 年度末の平均利用者数/日 | B5: 0 | C5: =INDEX(月次シミュレーション!$D$6:$D$41,12) -> 18 | D5: =INDEX(月次シミュレーション!$D$6:$D$41,24) -> 18 | E5: =INDEX(月次シミュレーション!$D$6:$D$41,36) -> 18 | F5: =E5 -> 18
A6: 延べ利用（人日） | B6: 0 | C6: =SUMIFS(月次シミュレーション!$E$6:$E$41,月次シミュレーション!$C$6:$C$41,1) -> 3058 | D6: =SUMIFS(月次シミュレーション!$E$6:$E$41,月次シミュレーション!$C$6:$C$41,2) -> 4752 | E6: =SUMIFS(月次シミュレーション!$E$6:$E$41,月次シミュレーション!$C$6:$C$41,3) -> 4752 | F6: =SUM(B6:E6) -> 12562
A7: 基本報酬 | B7: 0 | C7: =SUMIFS(月次シミュレーション!$H$6:$H$41,月次シミュレーション!$C$6:$C$41,1) -> 20251055 | D7: =SUMIFS(月次シミュレーション!$H$6:$H$41,月次シミュレーション!$C$6:$C$41,2) -> 31469265 | E7: =SUMIFS(月次シミュレーション!$H$6:$H$41,月次シミュレーション!$C$6:$C$41,3) -> 32872055 | F7: =SUM(B7:E7) -> 84592374
A8: 加算 | B8: 0 | C8: =SUMIFS(月次シミュレーション!$I$6:$I$41,月次シミュレーション!$C$6:$C$41,1) -> 1541232 | D8: =SUMIFS(月次シミュレーション!$I$6:$I$41,月次シミュレーション!$C$6:$C$41,2) -> 2395008 | E8: =SUMIFS(月次シミュレーション!$I$6:$I$41,月次シミュレーション!$C$6:$C$41,3) -> 2395008 | F8: =SUM(B8:E8) -> 6331248
A9: 処遇改善加算 | B9: 0 | C9: =SUMIFS(月次シミュレーション!$J$6:$J$41,月次シミュレーション!$C$6:$C$41,1) -> 2026682.7 | D9: =SUMIFS(月次シミュレーション!$J$6:$J$41,月次シミュレーション!$C$6:$C$41,2) -> 3149377.4 | E9: =SUMIFS(月次シミュレーション!$J$6:$J$41,月次シミュレーション!$C$6:$C$41,3) -> 3279836.9 | F9: =SUM(B9:E9) -> 8455896.9
A10: 給付費 合計 | B10: 0 | C10: =SUMIFS(月次シミュレーション!$K$6:$K$41,月次シミュレーション!$C$6:$C$41,1) -> 23818969 | D10: =SUMIFS(月次シミュレーション!$K$6:$K$41,月次シミュレーション!$C$6:$C$41,2) -> 37013650 | E10: =SUMIFS(月次シミュレーション!$K$6:$K$41,月次シミュレーション!$C$6:$C$41,3) -> 38546900 | F10: =SUM(B10:E10) -> 99379519
A11: 人件費（処遇改善分含む） | B11: 0 | C11: =SUMIFS(月次シミュレーション!$M$6:$M$41,月次シミュレーション!$C$6:$C$41,1)+SUMIFS(月次シミュレーション!$N$6:$N$41,月次シミュレーション!$C$6:$C$41,1) -> 16933308 | D11: =SUMIFS(月次シミュレーション!$M$6:$M$41,月次シミュレーション!$C$6:$C$41,2)+SUMIFS(月次シミュレーション!$N$6:$N$41,月次シミュレーション!$C$6:$C$41,2) -> 20370377 | E11: =SUMIFS(月次シミュレーション!$M$6:$M$41,月次シミュレーション!$C$6:$C$41,3)+SUMIFS(月次シミュレーション!$N$6:$N$41,月次シミュレーション!$C$6:$C$41,3) -> 20500837 | F11: =SUM(B11:E11) -> 57804522
A12: 家賃・車両・光熱等 | B12: 0 | C12: =SUMIFS(月次シミュレーション!$O$6:$O$41,月次シミュレーション!$C$6:$C$41,1) -> 3720000 | D12: =SUMIFS(月次シミュレーション!$O$6:$O$41,月次シミュレーション!$C$6:$C$41,2) -> 3720000 | E12: =SUMIFS(月次シミュレーション!$O$6:$O$41,月次シミュレーション!$C$6:$C$41,3) -> 3720000 | F12: =SUM(B12:E12) -> 11160000
A13: 変動費 | B13: 0 | C13: =SUMIFS(月次シミュレーション!$P$6:$P$41,月次シミュレーション!$C$6:$C$41,1) -> 611600 | D13: =SUMIFS(月次シミュレーション!$P$6:$P$41,月次シミュレーション!$C$6:$C$41,2) -> 950400 | E13: =SUMIFS(月次シミュレーション!$P$6:$P$41,月次シミュレーション!$C$6:$C$41,3) -> 950400 | F13: =SUM(B13:E13) -> 2512400
A14: 本部費 | B14: 0 | C14: =SUMIFS(月次シミュレーション!$Q$6:$Q$41,月次シミュレーション!$C$6:$C$41,1) -> 714569.08 | D14: =SUMIFS(月次シミュレーション!$Q$6:$Q$41,月次シミュレーション!$C$6:$C$41,2) -> 1110409.5 | E14: =SUMIFS(月次シミュレーション!$Q$6:$Q$41,月次シミュレーション!$C$6:$C$41,3) -> 1156407 | F14: =SUM(B14:E14) -> 2981385.6
A15: 減価償却 | B15: 0 | C15: =SUMIFS(月次シミュレーション!$R$6:$R$41,月次シミュレーション!$C$6:$C$41,1) -> 800000 | D15: =SUMIFS(月次シミュレーション!$R$6:$R$41,月次シミュレーション!$C$6:$C$41,2) -> 800000 | E15: =SUMIFS(月次シミュレーション!$R$6:$R$41,月次シミュレーション!$C$6:$C$41,3) -> 800000 | F15: =SUM(B15:E15) -> 2400000
A16: 開設準備費 | B16: =前提条件!$B$38 -> 2000000 | C16: 0 | D16: 0 | E16: 0 | F16: =SUM(B16:E16) -> 2000000
A17: 費用 合計 | B17: =SUM(B11:B16) -> 2000000 | C17: =SUM(C11:C16) -> 22779477 | D17: =SUM(D11:D16) -> 26951187 | E17: =SUM(E11:E16) -> 27127644 | F17: =SUM(B17:E17) -> 78858307
A18: 営業利益 | B18: =B10-B17 -> -2000000 | C18: =C10-C17 -> 1039492.5 | D18: =D10-D17 -> 10062463 | E18: =E10-E17 -> 11419256 | F18: =SUM(B18:E18) -> 20521212
A19: 営業利益率 | B19: =IF(B10=0,0,B18/B10) -> 0 | C19: =IF(C10=0,0,C18/C10) -> 0.043641371 | D19: =IF(D10=0,0,D18/D10) -> 0.27185817 | E19: =IF(E10=0,0,E18/E10) -> 0.29624318 | F19: =IF(F10=0,0,F18/F10) -> 0.20649337
A20: 年度末の資金残高 | B20: =月次シミュレーション!$Y$5 -> -9000000 | C20: =INDEX(月次シミュレーション!$Y$6:$Y$41,12) -> -13158090 | D20: =INDEX(月次シミュレーション!$Y$6:$Y$41,24) -> -2466986 | E20: =INDEX(月次シミュレーション!$Y$6:$Y$41,36) -> 9496728.3 | F20: =E20 -> 9496728.3
A22: ■ 重要指標
A23: 単月黒字になる月（開設から） | B23: =IFERROR(MATCH(1,月次シミュレーション!$Z$6:$Z$41,0)&"か月目","36か月内は未達") -> 6か月目
A24: 単月黒字になる年月 | B24: =IFERROR(INDEX(月次シミュレーション!$B$6:$B$41,MATCH(1,月次シミュレーション!$Z$6:$Z$41,0)),"-") -> 46631
A25: 初期投資を回収する月（資金残高がプラス） | B25: =IFERROR(MATCH(1,月次シミュレーション!$AA$6:$AA$41,0)&"か月目","36か月内は未達") -> 27か月目
A26: 資金残高の最低額（必要な運転資金の目安） | B26: =MIN(月次シミュレーション!$Y$5:$Y$41) -> -14350651
A27: 初期投資の合計 | B27: =前提条件!$B$36+前提条件!$B$37+前提条件!$B$38+前提条件!$B$39 -> 9000000

Sheet 感度分析
A1: 感度分析：安定期の年間営業利益（円）
A2: 行＝1日の平均利用者数、列＝基本報酬の区分（平均工賃月額）。新規特例・加算・人件費などは「前提条件」の値を使用。
B3: 1万〜1.8万円 | C3: 1.8万〜2.3万円 | D3: 2.3万〜2.8万円 | E3: 2.8万〜3.3万円 | F3: 3.3万〜3.8万円
A4: 平均利用者数/日 ＼ 基本報酬単位 | B4: 673 | C4: 703 | D4: 726 | E4: 738 | F4: 758
A5: 10 | B5: =12*(($A5*前提条件!$B$9*(B$4*前提条件!$B$13+前提条件!$B$14*2*前提条件!$B$15+前提条件!$B$16*前提条件!$B$17+前提条件!$B$18)*前提条件!$B$10)-(((前提条件!$B$21+MAX(前提条件!$B$24,CEILING($A5/前提条件!$B$23,0.5))*前提条件!$B$22)*(12+前提条件!$B$25)/12*(1+前提条件!$B$26)+前提条件!$B$27)+前提条件!$B$29+前提条件!$B$30+前提条件!$B$31+前提条件!$B$32+$A5*前提条件!$B$9*前提条件!$B$33+($A5*前提条件!$B$9*(B$4*前提条件!$B$13+前提条件!$B$14*2*前提条件!$B$15+前提条件!$B$16*前提条件!$B$17+前提条件!$B$18)*前提条件!$B$10)*(1+前提条件!$B$19)*前提条件!$B$34+前提条件!$B$36/120+前提条件!$B$37/60)) -> -369409.37 | C5: =12*(($A5*前提条件!$B$9*(C$4*前提条件!$B$13+前提条件!$B$14*2*前提条件!$B$15+前提条件!$B$16*前提条件!$B$17+前提条件!$B$18)*前提条件!$B$10)-(((前提条件!$B$21+MAX(前提条件!$B$24,CEILING($A5/前提条件!$B$23,0.5))*前提条件!$B$22)*(12+前提条件!$B$25)/12*(1+前提条件!$B$26)+前提条件!$B$27)+前提条件!$B$29+前提条件!$B$30+前提条件!$B$31+前提条件!$B$32+$A5*前提条件!$B$9*前提条件!$B$33+($A5*前提条件!$B$9*(C$4*前提条件!$B$13+前提条件!$B$14*2*前提条件!$B$15+前提条件!$B$16*前提条件!$B$17+前提条件!$B$18)*前提条件!$B$10)*(1+前提条件!$B$19)*前提条件!$B$34+前提条件!$B$36/120+前提条件!$B$37/60)) -> 384364.47 | D5: =12*(($A5*前提条件!$B$9*(D$4*前提条件!$B$13+前提条件!$B$14*2*前提条件!$B$15+前提条件!$B$16*前提条件!$B$17+前提条件!$B$18)*前提条件!$B$10)-(((前提条件!$B$21+MAX(前提条件!$B$24,CEILING($A5/前提条件!$B$23,0.5))*前提条件!$B$22)*(12+前提条件!$B$25)/12*(1+前提条件!$B$26)+前提条件!$B$27)+前提条件!$B$29+前提条件!$B$30+前提条件!$B$31+前提条件!$B$32+$A5*前提条件!$B$9*前提条件!$B$33+($A5*前提条件!$B$9*(D$4*前提条件!$B$13+前提条件!$B$14*2*前提条件!$B$15+前提条件!$B$16*前提条件!$B$17+前提条件!$B$18)*前提条件!$B$10)*(1+前提条件!$B$19)*前提条件!$B$34+前提条件!$B$36/120+前提条件!$B$37/60)) -> 962257.74 | E5: =12*(($A5*前提条件!$B$9*(E$4*前提条件!$B$13+前提条件!$B$14*2*前提条件!$B$15+前提条件!$B$16*前提条件!$B$17+前提条件!$B$18)*前提条件!$B$10)-(((前提条件!$B$21+MAX(前提条件!$B$24,CEILING($A5/前提条件!$B$23,0.5))*前提条件!$B$22)*(12+前提条件!$B$25)/12*(1+前提条件!$B$26)+前提条件!$B$27)+前提条件!$B$29+前提条件!$B$30+前提条件!$B$31+前提条件!$B$32+$A5*前提条件!$B$9*前提条件!$B$33+($A5*前提条件!$B$9*(E$4*前提条件!$B$13+前提条件!$B$14*2*前提条件!$B$15+前提条件!$B$16*前提条件!$B$17+前提条件!$B$18)*前提条件!$B$10)*(1+前提条件!$B$19)*前提条件!$B$34+前提条件!$B$36/120+前提条件!$B$37/60)) -> 1263767.3 | F5: =12*(($A5*前提条件!$B$9*(F$4*前提条件!$B$13+前提条件!$B$14*2*前提条件!$B$15+前提条件!$B$16*前提条件!$B$17+前提条件!$B$18)*前提条件!$B$10)-(((前提条件!$B$21+MAX(前提条件!$B$24,CEILING($A5/前提条件!$B$23,0.5))*前提条件!$B$22)*(12+前提条件!$B$25)/12*(1+前提条件!$B$26)+前提条件!$B$27)+前提条件!$B$29+前提条件!$B$30+前提条件!$B$31+前提条件!$B$32+$A5*前提条件!$B$9*前提条件!$B$33+($A5*前提条件!$B$9*(F$4*前提条件!$B$13+前提条件!$B$14*2*前提条件!$B$15+前提条件!$B$16*前提条件!$B$17+前提条件!$B$18)*前提条件!$B$10)*(1+前提条件!$B$19)*前提条件!$B$34+前提条件!$B$36/120+前提条件!$B$37/60)) -> 1766283.2
A6: 11 | B6: =12*(($A6*前提条件!$B$9*(B$4*前提条件!$B$13+前提条件!$B$14*2*前提条件!$B$15+前提条件!$B$16*前提条件!$B$17+前提条件!$B$18)*前提条件!$B$10)-(((前提条件!$B$21+MAX(前提条件!$B$24,CEILING($A6/前提条件!$B$23,0.5))*前提条件!$B$22)*(12+前提条件!$B$25)/12*(1+前提条件!$B$26)+前提条件!$B$27)+前提条件!$B$29+前提条件!$B$30+前提条件!$B$31+前提条件!$B$32+$A6*前提条件!$B$9*前提条件!$B$33+($A6*前提条件!$B$9*(B$4*前提条件!$B$13+前提条件!$B$14*2*前提条件!$B$15+前提条件!$B$16*前提条件!$B$17+前提条件!$B$18)*前提条件!$B$10)*(1+前提条件!$B$19)*前提条件!$B$34+前提条件!$B$36/120+前提条件!$B$37/60)) -> 1397449.7 | C6: =12*(($A6*前提条件!$B$9*(C$4*前提条件!$B$13+前提条件!$B$14*2*前提条件!$B$15+前提条件!$B$16*前提条件!$B$17+前提条件!$B$18)*前提条件!$B$10)-(((前提条件!$B$21+MAX(前提条件!$B$24,CEILING($A6/前提条件!$B$23,0.5))*前提条件!$B$22)*(12+前提条件!$B$25)/12*(1+前提条件!$B$26)+前提条件!$B$27)+前提条件!$B$29+前提条件!$B$30+前提条件!$B$31+前提条件!$B$32+$A6*前提条件!$B$9*前提条件!$B$33+($A6*前提条件!$B$9*(C$4*前提条件!$B$13+前提条件!$B$14*2*前提条件!$B$15+前提条件!$B$16*前提条件!$B$17+前提条件!$B$18)*前提条件!$B$10)*(1+前提条件!$B$19)*前提条件!$B$34+前提条件!$B$36/120+前提条件!$B$37/60)) -> 2226600.9 | D6: =12*(($A6*前提条件!$B$9*(D$4*前提条件!$B$13+前提条件!$B$14*2*前提条件!$B$15+前提条件!$B$16*前提条件!$B$17+前提条件!$B$18)*前提条件!$B$10)-(((前提条件!$B$21+MAX(前提条件!$B$24,CEILING($A6/前提条件!$B$23,0.5))*前提条件!$B$22)*(12+前提条件!$B$25)/12*(1+前提条件!$B$26)+前提条件!$B$27)+前提条件!$B$29+前提条件!$B$30+前提条件!$B$31+前提条件!$B$32+$A6*前提条件!$B$9*前提条件!$B$33+($A6*前提条件!$B$9*(D$4*前提条件!$B$13+前提条件!$B$14*2*前提条件!$B$15+前提条件!$B$16*前提条件!$B$17+前提条件!$B$18)*前提条件!$B$10)*(1+前提条件!$B$19)*前提条件!$B$34+前提条件!$B$36/120+前提条件!$B$37/60)) -> 2862283.5 | E6: =12*(($A6*前提条件!$B$9*(E$4*前提条件!$B$13+前提条件!$B$14*2*前提条件!$B$15+前提条件!$B$16*前提条件!$B$17+前提条件!$B$18)*前提条件!$B$10)-(((前提条件!$B$21+MAX(前提条件!$B$24,CEILING($A6/前提条件!$B$23,0.5))*前提条件!$B$22)*(12+前提条件!$B$25)/12*(1+前提条件!$B$26)+前提条件!$B$27)+前提条件!$B$29+前提条件!$B$30+前提条件!$B$31+前提条件!$B$32+$A6*前提条件!$B$9*前提条件!$B$33+($A6*前提条件!$B$9*(E$4*前提条件!$B$13+前提条件!$B$14*2*前提条件!$B$15+前提条件!$B$16*前提条件!$B$17+前提条件!$B$18)*前提条件!$B$10)*(1+前提条件!$B$19)*前提条件!$B$34+前提条件!$B$36/120+前提条件!$B$37/60)) -> 3193944 | F6: =12*(($A6*前提条件!$B$9*(F$4*前提条件!$B$13+前提条件!$B$14*2*前提条件!$B$15+前提条件!$B$16*前提条件!$B$17+前提条件!$B$18)*前提条件!$B$10)-(((前提条件!$B$21+MAX(前提条件!$B$24,CEILING($A6/前提条件!$B$23,0.5))*前提条件!$B$22)*(12+前提条件!$B$25)/12*(1+前提条件!$B$26)+前提条件!$B$27)+前提条件!$B$29+前提条件!$B$30+前提条件!$B$31+前提条件!$B$32+$A6*前提条件!$B$9*前提条件!$B$33+($A6*前提条件!$B$9*(F$4*前提条件!$B$13+前提条件!$B$14*2*前提条件!$B$15+前提条件!$B$16*前提条件!$B$17+前提条件!$B$18)*前提条件!$B$10)*(1+前提条件!$B$19)*前提条件!$B$34+前提条件!$B$36/120+前提条件!$B$37/60)) -> 3746711.5
A7: 12 | B7: =12*(($A7*前提条件!$B$9*(B$4*前提条件!$B$13+前提条件!$B$14*2*前提条件!$B$15+前提条件!$B$16*前提条件!$B$17+前提条件!$B$18)*前提条件!$B$10)-(((前提条件!$B$21+MAX(前提条件!$B$24,CEILING($A7/前提条件!$B$23,0.5))*前提条件!$B$22)*(12+前提条件!$B$25)/12*(1+前提条件!$B$26)+前提条件!$B$27)+前提条件!$B$29+前提条件!$B$30+前提条件!$B$31+前提条件!$B$32+$A7*前提条件!$B$9*前提条件!$B$33+($A7*前提条件!$B$9*(B$4*前提条件!$B$13+前提条件!$B$14*2*前提条件!$B$15+前提条件!$B$16*前提条件!$B$17+前提条件!$B$18)*前提条件!$B$10)*(1+前提条件!$B$19)*前提条件!$B$34+前提条件!$B$36/120+前提条件!$B$37/60)) -> 3164308.8 | C7: =12*(($A7*前提条件!$B$9*(C$4*前提条件!$B$13+前提条件!$B$14*2*前提条件!$B$15+前提条件!$B$16*前提条件!$B$17+前提条件!$B$18)*前提条件!$B$10)-(((前提条件!$B$21+MAX(前提条件!$B$24,CEILING($A7/前提条件!$B$23,0.5))*前提条件!$B$22)*(12+前提条件!$B$25)/12*(1+前提条件!$B$26)+前提条件!$B$27)+前提条件!$B$29+前提条件!$B$30+前提条件!$B$31+前提条件!$B$32+$A7*前提条件!$B$9*前提条件!$B$33+($A7*前提条件!$B$9*(C$4*前提条件!$B$13+前提条件!$B$14*2*前提条件!$B$15+前提条件!$B$16*前提条件!$B$17+前提条件!$B$18)*前提条件!$B$10)*(1+前提条件!$B$19)*前提条件!$B$34+前提条件!$B$36/120+前提条件!$B$37/60)) -> 4068837.4 | D7: =12*(($A7*前提条件!$B$9*(D$4*前提条件!$B$13+前提条件!$B$14*2*前提条件!$B$15+前提条件!$B$16*前提条件!$B$17+前提条件!$B$18)*前提条件!$B$10)-(((前提条件!$B$21+MAX(前提条件!$B$24,CEILING($A7/前提条件!$B$23,0.5))*前提条件!$B$22)*(12+前提条件!$B$25)/12*(1+前提条件!$B$26)+前提条件!$B$27)+前提条件!$B$29+前提条件!$B$30+前提条件!$B$31+前提条件!$B$32+$A7*前提条件!$B$9*前提条件!$B$33+($A7*前提条件!$B$9*(D$4*前提条件!$B$13+前提条件!$B$14*2*前提条件!$B$15+前提条件!$B$16*前提条件!$B$17+前提条件!$B$18)*前提条件!$B$10)*(1+前提条件!$B$19)*前提条件!$B$34+前提条件!$B$36/120+前提条件!$B$37/60)) -> 4762309.3 | E7: =12*(($A7*前提条件!$B$9*(E$4*前提条件!$B$13+前提条件!$B$14*2*前提条件!$B$15+前提条件!$B$16*前提条件!$B$17+前提条件!$B$18)*前提条件!$B$10)-(((前提条件!$B$21+MAX(前提条件!$B$24,CEILING($A7/前提条件!$B$23,0.5))*前提条件!$B$22)*(12+前提条件!$B$25)/12*(1+前提条件!$B$26)+前提条件!$B$27)+前提条件!$B$29+前提条件!$B$30+前提条件!$B$31+前提条件!$B$32+$A7*前提条件!$B$9*前提条件!$B$33+($A7*前提条件!$B$9*(E$4*前提条件!$B$13+前提条件!$B$14*2*前提条件!$B$15+前提条件!$B$16*前提条件!$B$17+前提条件!$B$18)*前提条件!$B$10)*(1+前提条件!$B$19)*前提条件!$B$34+前提条件!$B$36/120+前提条件!$B$37/60)) -> 5124120.7 | F7: =12*(($A7*前提条件!$B$9*(F$4*前提条件!$B$13+前提条件!$B$14*2*前提条件!$B$15+前提条件!$B$16*前提条件!$B$17+前提条件!$B$18)*前提条件!$B$10)-(((前提条件!$B$21+MAX(前提条件!$B$24,CEILING($A7/前提条件!$B$23,0.5))*前提条件!$B$22)*(12+前提条件!$B$25)/12*(1+前提条件!$B$26)+前提条件!$B$27)+前提条件!$B$29+前提条件!$B$30+前提条件!$B$31+前提条件!$B$32+$A7*前提条件!$B$9*前提条件!$B$33+($A7*前提条件!$B$9*(F$4*前提条件!$B$13+前提条件!$B$14*2*前提条件!$B$15+前提条件!$B$16*前提条件!$B$17+前提条件!$B$18)*前提条件!$B$10)*(1+前提条件!$B$19)*前提条件!$B$34+前提条件!$B$36/120+前提条件!$B$37/60)) -> 5727139.8
A8: 13 | B8: =12*(($A8*前提条件!$B$9*(B$4*前提条件!$B$13+前提条件!$B$14*2*前提条件!$B$15+前提条件!$B$16*前提条件!$B$17+前提条件!$B$18)*前提条件!$B$10)-(((前提条件!$B$21+MAX(前提条件!$B$24,CEILING($A8/前提条件!$B$23,0.5))*前提条件!$B$22)*(12+前提条件!$B$25)/12*(1+前提条件!$B$26)+前提条件!$B$27)+前提条件!$B$29+前提条件!$B$30+前提条件!$B$31+前提条件!$B$32+$A8*前提条件!$B$9*前提条件!$B$33+($A8*前提条件!$B$9*(B$4*前提条件!$B$13+前提条件!$B$14*2*前提条件!$B$15+前提条件!$B$16*前提条件!$B$17+前提条件!$B$18)*前提条件!$B$10)*(1+前提条件!$B$19)*前提条件!$B$34+前提条件!$B$36/120+前提条件!$B$37/60)) -> 3079667.8 | C8: =12*(($A8*前提条件!$B$9*(C$4*前提条件!$B$13+前提条件!$B$14*2*前提条件!$B$15+前提条件!$B$16*前提条件!$B$17+前提条件!$B$18)*前提条件!$B$10)-(((前提条件!$B$21+MAX(前提条件!$B$24,CEILING($A8/前提条件!$B$23,0.5))*前提条件!$B$22)*(12+前提条件!$B$25)/12*(1+前提条件!$B$26)+前提条件!$B$27)+前提条件!$B$29+前提条件!$B$30+前提条件!$B$31+前提条件!$B$32+$A8*前提条件!$B$9*前提条件!$B$33+($A8*前提条件!$B$9*(C$4*前提条件!$B$13+前提条件!$B$14*2*前提条件!$B$15+前提条件!$B$16*前提条件!$B$17+前提条件!$B$18)*前提条件!$B$10)*(1+前提条件!$B$19)*前提条件!$B$34+前提条件!$B$36/120+前提条件!$B$37/60)) -> 4059573.8 | D8: =12*(($A8*前提条件!$B$9*(D$4*前提条件!$B$13+前提条件!$B$14*2*前提条件!$B$15+前提条件!$B$16*前提条件!$B$17+前提条件!$B$18)*前提条件!$B$10)-(((前提条件!$B$21+MAX(前提条件!$B$24,CEILING($A8/前提条件!$B$23,0.5))*前提条件!$B$22)*(12+前提条件!$B$25)/12*(1+前提条件!$B$26)+前提条件!$B$27)+前提条件!$B$29+前提条件!$B$30+前提条件!$B$31+前提条件!$B$32+$A8*前提条件!$B$9*前提条件!$B$33+($A8*前提条件!$B$9*(D$4*前提条件!$B$13+前提条件!$B$14*2*前提条件!$B$15+前提条件!$B$16*前提条件!$B$17+前提条件!$B$18)*前提条件!$B$10)*(1+前提条件!$B$19)*前提条件!$B$34+前提条件!$B$36/120+前提条件!$B$37/60)) -> 4810835.1 | E8: =12*(($A8*前提条件!$B$9*(E$4*前提条件!$B$13+前提条件!$B$14*2*前提条件!$B$15+前提条件!$B$16*前提条件!$B$17+前提条件!$B$18)*前提条件!$B$10)-(((前提条件!$B$21+MAX(前提条件!$B$24,CEILING($A8/前提条件!$B$23,0.5))*前提条件!$B$22)*(12+前提条件!$B$25)/12*(1+前提条件!$B$26)+前提条件!$B$27)+前提条件!$B$29+前提条件!$B$30+前提条件!$B$31+前提条件!$B$32+$A8*前提条件!$B$9*前提条件!$B$33+($A8*前提条件!$B$9*(E$4*前提条件!$B$13+前提条件!$B$14*2*前提条件!$B$15+前提条件!$B$16*前提条件!$B$17+前提条件!$B$18)*前提条件!$B$10)*(1+前提条件!$B$19)*前提条件!$B$34+前提条件!$B$36/120+前提条件!$B$37/60)) -> 5202797.5 | F8: =12*(($A8*前提条件!$B$9*(F$4*前提条件!$B$13+前提条件!$B$14*2*前提条件!$B$15+前提条件!$B$16*前提条件!$B$17+前提条件!$B$18)*前提条件!$B$10)-(((前提条件!$B$21+MAX(前提条件!$B$24,CEILING($A8/前提条件!$B$23,0.5))*前提条件!$B$22)*(12+前提条件!$B$25)/12*(1+前提条件!$B$26)+前提条件!$B$27)+前提条件!$B$29+前提条件!$B$30+前提条件!$B$31+前提条件!$B$32+$A8*前提条件!$B$9*前提条件!$B$33+($A8*前提条件!$B$9*(F$4*前提条件!$B$13+前提条件!$B$14*2*前提条件!$B$15+前提条件!$B$16*前提条件!$B$17+前提条件!$B$18)*前提条件!$B$10)*(1+前提条件!$B$19)*前提条件!$B$34+前提条件!$B$36/120+前提条件!$B$37/60)) -> 5856068.1
A9: 14 | B9: =12*(($A9*前提条件!$B$9*(B$4*前提条件!$B$13+前提条件!$B$14*2*前提条件!$B$15+前提条件!$B$16*前提条件!$B$17+前提条件!$B$18)*前提条件!$B$10)-(((前提条件!$B$21+MAX(前提条件!$B$24,CEILING($A9/前提条件!$B$23,0.5))*前提条件!$B$22)*(12+前提条件!$B$25)/12*(1+前提条件!$B$26)+前提条件!$B$27)+前提条件!$B$29+前提条件!$B$30+前提条件!$B$31+前提条件!$B$32+$A9*前提条件!$B$9*前提条件!$B$33+($A9*前提条件!$B$9*(B$4*前提条件!$B$13+前提条件!$B$14*2*前提条件!$B$15+前提条件!$B$16*前提条件!$B$17+前提条件!$B$18)*前提条件!$B$10)*(1+前提条件!$B$19)*前提条件!$B$34+前提条件!$B$36/120+前提条件!$B$37/60)) -> 4846526.9 | C9: =12*(($A9*前提条件!$B$9*(C$4*前提条件!$B$13+前提条件!$B$14*2*前提条件!$B$15+前提条件!$B$16*前提条件!$B$17+前提条件!$B$18)*前提条件!$B$10)-(((前提条件!$B$21+MAX(前提条件!$B$24,CEILING($A9/前提条件!$B$23,0.5))*前提条件!$B$22)*(12+前提条件!$B$25)/12*(1+前提条件!$B$26)+前提条件!$B$27)+前提条件!$B$29+前提条件!$B$30+前提条件!$B$31+前提条件!$B$32+$A9*前提条件!$B$9*前提条件!$B$33+($A9*前提条件!$B$9*(C$4*前提条件!$B$13+前提条件!$B$14*2*前提条件!$B$15+前提条件!$B$16*前提条件!$B$17+前提条件!$B$18)*前提条件!$B$10)*(1+前提条件!$B$19)*前提条件!$B$34+前提条件!$B$36/120+前提条件!$B$37/60)) -> 5901810.3 | D9: =12*(($A9*前提条件!$B$9*(D$4*前提条件!$B$13+前提条件!$B$14*2*前提条件!$B$15+前提条件!$B$16*前提条件!$B$17+前提条件!$B$18)*前提条件!$B$10)-(((前提条件!$B$21+MAX(前提条件!$B$24,CEILING($A9/前提条件!$B$23,0.5))*前提条件!$B$22)*(12+前提条件!$B$25)/12*(1+前提条件!$B$26)+前提条件!$B$27)+前提条件!$B$29+前提条件!$B$30+前提条件!$B$31+前提条件!$B$32+$A9*前提条件!$B$9*前提条件!$B$33+($A9*前提条件!$B$9*(D$4*前提条件!$B$13+前提条件!$B$14*2*前提条件!$B$15+前提条件!$B$16*前提条件!$B$17+前提条件!$B$18)*前提条件!$B$10)*(1+前提条件!$B$19)*前提条件!$B$34+前提条件!$B$36/120+前提条件!$B$37/60)) -> 6710860.8 | E9: =12*(($A9*前提条件!$B$9*(E$4*前提条件!$B$13+前提条件!$B$14*2*前提条件!$B$15+前提条件!$B$16*前提条件!$B$17+前提条件!$B$18)*前提条件!$B$10)-(((前提条件!$B$21+MAX(前提条件!$B$24,CEILING($A9/前提条件!$B$23,0.5))*前提条件!$B$22)*(12+前提条件!$B$25)/12*(1+前提条件!$B$26)+前提条件!$B$27)+前提条件!$B$29+前提条件!$B$30+前提条件!$B$31+前提条件!$B$32+$A9*前提条件!$B$9*前提条件!$B$33+($A9*前提条件!$B$9*(E$4*前提条件!$B$13+前提条件!$B$14*2*前提条件!$B$15+前提条件!$B$16*前提条件!$B$17+前提条件!$B$18)*前提条件!$B$10)*(1+前提条件!$B$19)*前提条件!$B$34+前提条件!$B$36/120+前提条件!$B$37/60)) -> 7132974.2 | F9: =12*(($A9*前提条件!$B$9*(F$4*前提条件!$B$13+前提条件!$B$14*2*前提条件!$B$15+前提条件!$B$16*前提条件!$B$17+前提条件!$B$18)*前提条件!$B$10)-(((前提条件!$B$21+MAX(前提条件!$B$24,CEILING($A9/前提条件!$B$23,0.5))*前提条件!$B$22)*(12+前提条件!$B$25)/12*(1+前提条件!$B$26)+前提条件!$B$27)+前提条件!$B$29+前提条件!$B$30+前提条件!$B$31+前提条件!$B$32+$A9*前提条件!$B$9*前提条件!$B$33+($A9*前提条件!$B$9*(F$4*前提条件!$B$13+前提条件!$B$14*2*前提条件!$B$15+前提条件!$B$16*前提条件!$B$17+前提条件!$B$18)*前提条件!$B$10)*(1+前提条件!$B$19)*前提条件!$B$34+前提条件!$B$36/120+前提条件!$B$37/60)) -> 7836496.4
A10: 15 | B10: =12*(($A10*前提条件!$B$9*(B$4*前提条件!$B$13+前提条件!$B$14*2*前提条件!$B$15+前提条件!$B$16*前提条件!$B$17+前提条件!$B$18)*前提条件!$B$10)-(((前提条件!$B$21+MAX(前提条件!$B$24,CEILING($A10/前提条件!$B$23,0.5))*前提条件!$B$22)*(12+前提条件!$B$25)/12*(1+前提条件!$B$26)+前提条件!$B$27)+前提条件!$B$29+前提条件!$B$30+前提条件!$B$31+前提条件!$B$32+$A10*前提条件!$B$9*前提条件!$B$33+($A10*前提条件!$B$9*(B$4*前提条件!$B$13+前提条件!$B$14*2*前提条件!$B$15+前提条件!$B$16*前提条件!$B$17+前提条件!$B$18)*前提条件!$B$10)*(1+前提条件!$B$19)*前提条件!$B$34+前提条件!$B$36/120+前提条件!$B$37/60)) -> 6613386 | C10: =12*(($A10*前提条件!$B$9*(C$4*前提条件!$B$13+前提条件!$B$14*2*前提条件!$B$15+前提条件!$B$16*前提条件!$B$17+前提条件!$B$18)*前提条件!$B$10)-(((前提条件!$B$21+MAX(前提条件!$B$24,CEILING($A10/前提条件!$B$23,0.5))*前提条件!$B$22)*(12+前提条件!$B$25)/12*(1+前提条件!$B$26)+前提条件!$B$27)+前提条件!$B$29+前提条件!$B$30+前提条件!$B$31+前提条件!$B$32+$A10*前提条件!$B$9*前提条件!$B$33+($A10*前提条件!$B$9*(C$4*前提条件!$B$13+前提条件!$B$14*2*前提条件!$B$15+前提条件!$B$16*前提条件!$B$17+前提条件!$B$18)*前提条件!$B$10)*(1+前提条件!$B$19)*前提条件!$B$34+前提条件!$B$36/120+前提条件!$B$37/60)) -> 7744046.7 | D10: =12*(($A10*前提条件!$B$9*(D$4*前提条件!$B$13+前提条件!$B$14*2*前提条件!$B$15+前提条件!$B$16*前提条件!$B$17+前提条件!$B$18)*前提条件!$B$10)-(((前提条件!$B$21+MAX(前提条件!$B$24,CEILING($A10/前提条件!$B$23,0.5))*前提条件!$B$22)*(12+前提条件!$B$25)/12*(1+前提条件!$B$26)+前提条件!$B$27)+前提条件!$B$29+前提条件!$B$30+前提条件!$B$31+前提条件!$B$32+$A10*前提条件!$B$9*前提条件!$B$33+($A10*前提条件!$B$9*(D$4*前提条件!$B$13+前提条件!$B$14*2*前提条件!$B$15+前提条件!$B$16*前提条件!$B$17+前提条件!$B$18)*前提条件!$B$10)*(1+前提条件!$B$19)*前提条件!$B$34+前提条件!$B$36/120+前提条件!$B$37/60)) -> 8610886.6 | E10: =12*(($A10*前提条件!$B$9*(E$4*前提条件!$B$13+前提条件!$B$14*2*前提条件!$B$15+前提条件!$B$16*前提条件!$B$17+前提条件!$B$18)*前提条件!$B$10)-(((前提条件!$B$21+MAX(前提条件!$B$24,CEILING($A10/前提条件!$B$23,0.5))*前提条件!$B$22)*(12+前提条件!$B$25)/12*(1+前提条件!$B$26)+前提条件!$B$27)+前提条件!$B$29+前提条件!$B$30+前提条件!$B$31+前提条件!$B$32+$A10*前提条件!$B$9*前提条件!$B$33+($A10*前提条件!$B$9*(E$4*前提条件!$B$13+前提条件!$B$14*2*前提条件!$B$15+前提条件!$B$16*前提条件!$B$17+前提条件!$B$18)*前提条件!$B$10)*(1+前提条件!$B$19)*前提条件!$B$34+前提条件!$B$36/120+前提条件!$B$37/60)) -> 9063150.9 | F10: =12*(($A10*前提条件!$B$9*(F$4*前提条件!$B$13+前提条件!$B$14*2*前提条件!$B$15+前提条件!$B$16*前提条件!$B$17+前提条件!$B$18)*前提条件!$B$10)-(((前提条件!$B$21+MAX(前提条件!$B$24,CEILING($A10/前提条件!$B$23,0.5))*前提条件!$B$22)*(12+前提条件!$B$25)/12*(1+前提条件!$B$26)+前提条件!$B$27)+前提条件!$B$29+前提条件!$B$30+前提条件!$B$31+前提条件!$B$32+$A10*前提条件!$B$9*前提条件!$B$33+($A10*前提条件!$B$9*(F$4*前提条件!$B$13+前提条件!$B$14*2*前提条件!$B$15+前提条件!$B$16*前提条件!$B$17+前提条件!$B$18)*前提条件!$B$10)*(1+前提条件!$B$19)*前提条件!$B$34+前提条件!$B$36/120+前提条件!$B$37/60)) -> 9816924.7
A11: 16 | B11: =12*(($A11*前提条件!$B$9*(B$4*前提条件!$B$13+前提条件!$B$14*2*前提条件!$B$15+前提条件!$B$16*前提条件!$B$17+前提条件!$B$18)*前提条件!$B$10)-(((前提条件!$B$21+MAX(前提条件!$B$24,CEILING($A11/前提条件!$B$23,0.5))*前提条件!$B$22)*(12+前提条件!$B$25)/12*(1+前提条件!$B$26)+前提条件!$B$27)+前提条件!$B$29+前提条件!$B$30+前提条件!$B$31+前提条件!$B$32+$A11*前提条件!$B$9*前提条件!$B$33+($A11*前提条件!$B$9*(B$4*前提条件!$B$13+前提条件!$B$14*2*前提条件!$B$15+前提条件!$B$16*前提条件!$B$17+前提条件!$B$18)*前提条件!$B$10)*(1+前提条件!$B$19)*前提条件!$B$34+前提条件!$B$36/120+前提条件!$B$37/60)) -> 6528745 | C11: =12*(($A11*前提条件!$B$9*(C$4*前提条件!$B$13+前提条件!$B$14*2*前提条件!$B$15+前提条件!$B$16*前提条件!$B$17+前提条件!$B$18)*前提条件!$B$10)-(((前提条件!$B$21+MAX(前提条件!$B$24,CEILING($A11/前提条件!$B$23,0.5))*前提条件!$B$22)*(12+前提条件!$B$25)/12*(1+前提条件!$B$26)+前提条件!$B$27)+前提条件!$B$29+前提条件!$B$30+前提条件!$B$31+前提条件!$B$32+$A11*前提条件!$B$9*前提条件!$B$33+($A11*前提条件!$B$9*(C$4*前提条件!$B$13+前提条件!$B$14*2*前提条件!$B$15+前提条件!$B$16*前提条件!$B$17+前提条件!$B$18)*前提条件!$B$10)*(1+前提条件!$B$19)*前提条件!$B$34+前提条件!$B$36/120+前提条件!$B$37/60)) -> 7734783.1 | D11: =12*(($A11*前提条件!$B$9*(D$4*前提条件!$B$13+前提条件!$B$14*2*前提条件!$B$15+前提条件!$B$16*前提条件!$B$17+前提条件!$B$18)*前提条件!$B$10)-(((前提条件!$B$21+MAX(前提条件!$B$24,CEILING($A11/前提条件!$B$23,0.5))*前提条件!$B$22)*(12+前提条件!$B$25)/12*(1+前提条件!$B$26)+前提条件!$B$27)+前提条件!$B$29+前提条件!$B$30+前提条件!$B$31+前提条件!$B$32+$A11*前提条件!$B$9*前提条件!$B$33+($A11*前提条件!$B$9*(D$4*前提条件!$B$13+前提条件!$B$14*2*前提条件!$B$15+前提条件!$B$16*前提条件!$B$17+前提条件!$B$18)*前提条件!$B$10)*(1+前提条件!$B$19)*前提条件!$B$34+前提条件!$B$36/120+前提条件!$B$37/60)) -> 8659412.4 | E11: =12*(($A11*前提条件!$B$9*(E$4*前提条件!$B$13+前提条件!$B$14*2*前提条件!$B$15+前提条件!$B$16*前提条件!$B$17+前提条件!$B$18)*前提条件!$B$10)-(((前提条件!$B$21+MAX(前提条件!$B$24,CEILING($A11/前提条件!$B$23,0.5))*前提条件!$B$22)*(12+前提条件!$B$25)/12*(1+前提条件!$B$26)+前提条件!$B$27)+前提条件!$B$29+前提条件!$B$30+前提条件!$B$31+前提条件!$B$32+$A11*前提条件!$B$9*前提条件!$B$33+($A11*前提条件!$B$9*(E$4*前提条件!$B$13+前提条件!$B$14*2*前提条件!$B$15+前提条件!$B$16*前提条件!$B$17+前提条件!$B$18)*前提条件!$B$10)*(1+前提条件!$B$19)*前提条件!$B$34+前提条件!$B$36/120+前提条件!$B$37/60)) -> 9141827.6 | F11: =12*(($A11*前提条件!$B$9*(F$4*前提条件!$B$13+前提条件!$B$14*2*前提条件!$B$15+前提条件!$B$16*前提条件!$B$17+前提条件!$B$18)*前提条件!$B$10)-(((前提条件!$B$21+MAX(前提条件!$B$24,CEILING($A11/前提条件!$B$23,0.5))*前提条件!$B$22)*(12+前提条件!$B$25)/12*(1+前提条件!$B$26)+前提条件!$B$27)+前提条件!$B$29+前提条件!$B$30+前提条件!$B$31+前提条件!$B$32+$A11*前提条件!$B$9*前提条件!$B$33+($A11*前提条件!$B$9*(F$4*前提条件!$B$13+前提条件!$B$14*2*前提条件!$B$15+前提条件!$B$16*前提条件!$B$17+前提条件!$B$18)*前提条件!$B$10)*(1+前提条件!$B$19)*前提条件!$B$34+前提条件!$B$36/120+前提条件!$B$37/60)) -> 9945853.1
A12: 17 | B12: =12*(($A12*前提条件!$B$9*(B$4*前提条件!$B$13+前提条件!$B$14*2*前提条件!$B$15+前提条件!$B$16*前提条件!$B$17+前提条件!$B$18)*前提条件!$B$10)-(((前提条件!$B$21+MAX(前提条件!$B$24,CEILING($A12/前提条件!$B$23,0.5))*前提条件!$B$22)*(12+前提条件!$B$25)/12*(1+前提条件!$B$26)+前提条件!$B$27)+前提条件!$B$29+前提条件!$B$30+前提条件!$B$31+前提条件!$B$32+$A12*前提条件!$B$9*前提条件!$B$33+($A12*前提条件!$B$9*(B$4*前提条件!$B$13+前提条件!$B$14*2*前提条件!$B$15+前提条件!$B$16*前提条件!$B$17+前提条件!$B$18)*前提条件!$B$10)*(1+前提条件!$B$19)*前提条件!$B$34+前提条件!$B$36/120+前提条件!$B$37/60)) -> 8295604.1 | C12: =12*(($A12*前提条件!$B$9*(C$4*前提条件!$B$13+前提条件!$B$14*2*前提条件!$B$15+前提条件!$B$16*前提条件!$B$17+前提条件!$B$18)*前提条件!$B$10)-(((前提条件!$B$21+MAX(前提条件!$B$24,CEILING($A12/前提条件!$B$23,0.5))*前提条件!$B$22)*(12+前提条件!$B$25)/12*(1+前提条件!$B$26)+前提条件!$B$27)+前提条件!$B$29+前提条件!$B$30+前提条件!$B$31+前提条件!$B$32+$A12*前提条件!$B$9*前提条件!$B$33+($A12*前提条件!$B$9*(C$4*前提条件!$B$13+前提条件!$B$14*2*前提条件!$B$15+前提条件!$B$16*前提条件!$B$17+前提条件!$B$18)*前提条件!$B$10)*(1+前提条件!$B$19)*前提条件!$B$34+前提条件!$B$36/120+前提条件!$B$37/60)) -> 9577019.6 | D12: =12*(($A12*前提条件!$B$9*(D$4*前提条件!$B$13+前提条件!$B$14*2*前提条件!$B$15+前提条件!$B$16*前提条件!$B$17+前提条件!$B$18)*前提条件!$B$10)-(((前提条件!$B$21+MAX(前提条件!$B$24,CEILING($A12/前提条件!$B$23,0.5))*前提条件!$B$22)*(12+前提条件!$B$25)/12*(1+前提条件!$B$26)+前提条件!$B$27)+前提条件!$B$29+前提条件!$B$30+前提条件!$B$31+前提条件!$B$32+$A12*前提条件!$B$9*前提条件!$B$33+($A12*前提条件!$B$9*(D$4*前提条件!$B$13+前提条件!$B$14*2*前提条件!$B$15+前提条件!$B$16*前提条件!$B$17+前提条件!$B$18)*前提条件!$B$10)*(1+前提条件!$B$19)*前提条件!$B$34+前提条件!$B$36/120+前提条件!$B$37/60)) -> 10559438 | E12: =12*(($A12*前提条件!$B$9*(E$4*前提条件!$B$13+前提条件!$B$14*2*前提条件!$B$15+前提条件!$B$16*前提条件!$B$17+前提条件!$B$18)*前提条件!$B$10)-(((前提条件!$B$21+MAX(前提条件!$B$24,CEILING($A12/前提条件!$B$23,0.5))*前提条件!$B$22)*(12+前提条件!$B$25)/12*(1+前提条件!$B$26)+前提条件!$B$27)+前提条件!$B$29+前提条件!$B$30+前提条件!$B$31+前提条件!$B$32+$A12*前提条件!$B$9*前提条件!$B$33+($A12*前提条件!$B$9*(E$4*前提条件!$B$13+前提条件!$B$14*2*前提条件!$B$15+前提条件!$B$16*前提条件!$B$17+前提条件!$B$18)*前提条件!$B$10)*(1+前提条件!$B$19)*前提条件!$B$34+前提条件!$B$36/120+前提条件!$B$37/60)) -> 11072004 | F12: =12*(($A12*前提条件!$B$9*(F$4*前提条件!$B$13+前提条件!$B$14*2*前提条件!$B$15+前提条件!$B$16*前提条件!$B$17+前提条件!$B$18)*前提条件!$B$10)-(((前提条件!$B$21+MAX(前提条件!$B$24,CEILING($A12/前提条件!$B$23,0.5))*前提条件!$B$22)*(12+前提条件!$B$25)/12*(1+前提条件!$B$26)+前提条件!$B$27)+前提条件!$B$29+前提条件!$B$30+前提条件!$B$31+前提条件!$B$32+$A12*前提条件!$B$9*前提条件!$B$33+($A12*前提条件!$B$9*(F$4*前提条件!$B$13+前提条件!$B$14*2*前提条件!$B$15+前提条件!$B$16*前提条件!$B$17+前提条件!$B$18)*前提条件!$B$10)*(1+前提条件!$B$19)*前提条件!$B$34+前提条件!$B$36/120+前提条件!$B$37/60)) -> 11926281
A13: 18 | B13: =12*(($A13*前提条件!$B$9*(B$4*前提条件!$B$13+前提条件!$B$14*2*前提条件!$B$15+前提条件!$B$16*前提条件!$B$17+前提条件!$B$18)*前提条件!$B$10)-(((前提条件!$B$21+MAX(前提条件!$B$24,CEILING($A13/前提条件!$B$23,0.5))*前提条件!$B$22)*(12+前提条件!$B$25)/12*(1+前提条件!$B$26)+前提条件!$B$27)+前提条件!$B$29+前提条件!$B$30+前提条件!$B$31+前提条件!$B$32+$A13*前提条件!$B$9*前提条件!$B$33+($A13*前提条件!$B$9*(B$4*前提条件!$B$13+前提条件!$B$14*2*前提条件!$B$15+前提条件!$B$16*前提条件!$B$17+前提条件!$B$18)*前提条件!$B$10)*(1+前提条件!$B$19)*前提条件!$B$34+前提条件!$B$36/120+前提条件!$B$37/60)) -> 10062463 | C13: =12*(($A13*前提条件!$B$9*(C$4*前提条件!$B$13+前提条件!$B$14*2*前提条件!$B$15+前提条件!$B$16*前提条件!$B$17+前提条件!$B$18)*前提条件!$B$10)-(((前提条件!$B$21+MAX(前提条件!$B$24,CEILING($A13/前提条件!$B$23,0.5))*前提条件!$B$22)*(12+前提条件!$B$25)/12*(1+前提条件!$B$26)+前提条件!$B$27)+前提条件!$B$29+前提条件!$B$30+前提条件!$B$31+前提条件!$B$32+$A13*前提条件!$B$9*前提条件!$B$33+($A13*前提条件!$B$9*(C$4*前提条件!$B$13+前提条件!$B$14*2*前提条件!$B$15+前提条件!$B$16*前提条件!$B$17+前提条件!$B$18)*前提条件!$B$10)*(1+前提条件!$B$19)*前提条件!$B$34+前提条件!$B$36/120+前提条件!$B$37/60)) -> 11419256 | D13: =12*(($A13*前提条件!$B$9*(D$4*前提条件!$B$13+前提条件!$B$14*2*前提条件!$B$15+前提条件!$B$16*前提条件!$B$17+前提条件!$B$18)*前提条件!$B$10)-(((前提条件!$B$21+MAX(前提条件!$B$24,CEILING($A13/前提条件!$B$23,0.5))*前提条件!$B$22)*(12+前提条件!$B$25)/12*(1+前提条件!$B$26)+前提条件!$B$27)+前提条件!$B$29+前提条件!$B$30+前提条件!$B$31+前提条件!$B$32+$A13*前提条件!$B$9*前提条件!$B$33+($A13*前提条件!$B$9*(D$4*前提条件!$B$13+前提条件!$B$14*2*前提条件!$B$15+前提条件!$B$16*前提条件!$B$17+前提条件!$B$18)*前提条件!$B$10)*(1+前提条件!$B$19)*前提条件!$B$34+前提条件!$B$36/120+前提条件!$B$37/60)) -> 12459464 | E13: =12*(($A13*前提条件!$B$9*(E$4*前提条件!$B$13+前提条件!$B$14*2*前提条件!$B$15+前提条件!$B$16*前提条件!$B$17+前提条件!$B$18)*前提条件!$B$10)-(((前提条件!$B$21+MAX(前提条件!$B$24,CEILING($A13/前提条件!$B$23,0.5))*前提条件!$B$22)*(12+前提条件!$B$25)/12*(1+前提条件!$B$26)+前提条件!$B$27)+前提条件!$B$29+前提条件!$B$30+前提条件!$B$31+前提条件!$B$32+$A13*前提条件!$B$9*前提条件!$B$33+($A13*前提条件!$B$9*(E$4*前提条件!$B$13+前提条件!$B$14*2*前提条件!$B$15+前提条件!$B$16*前提条件!$B$17+前提条件!$B$18)*前提条件!$B$10)*(1+前提条件!$B$19)*前提条件!$B$34+前提条件!$B$36/120+前提条件!$B$37/60)) -> 13002181 | F13: =12*(($A13*前提条件!$B$9*(F$4*前提条件!$B$13+前提条件!$B$14*2*前提条件!$B$15+前提条件!$B$16*前提条件!$B$17+前提条件!$B$18)*前提条件!$B$10)-(((前提条件!$B$21+MAX(前提条件!$B$24,CEILING($A13/前提条件!$B$23,0.5))*前提条件!$B$22)*(12+前提条件!$B$25)/12*(1+前提条件!$B$26)+前提条件!$B$27)+前提条件!$B$29+前提条件!$B$30+前提条件!$B$31+前提条件!$B$32+$A13*前提条件!$B$9*前提条件!$B$33+($A13*前提条件!$B$9*(F$4*前提条件!$B$13+前提条件!$B$14*2*前提条件!$B$15+前提条件!$B$16*前提条件!$B$17+前提条件!$B$18)*前提条件!$B$10)*(1+前提条件!$B$19)*前提条件!$B$34+前提条件!$B$36/120+前提条件!$B$37/60)) -> 13906710
A14: 19 | B14: =12*(($A14*前提条件!$B$9*(B$4*前提条件!$B$13+前提条件!$B$14*2*前提条件!$B$15+前提条件!$B$16*前提条件!$B$17+前提条件!$B$18)*前提条件!$B$10)-(((前提条件!$B$21+MAX(前提条件!$B$24,CEILING($A14/前提条件!$B$23,0.5))*前提条件!$B$22)*(12+前提条件!$B$25)/12*(1+前提条件!$B$26)+前提条件!$B$27)+前提条件!$B$29+前提条件!$B$30+前提条件!$B$31+前提条件!$B$32+$A14*前提条件!$B$9*前提条件!$B$33+($A14*前提条件!$B$9*(B$4*前提条件!$B$13+前提条件!$B$14*2*前提条件!$B$15+前提条件!$B$16*前提条件!$B$17+前提条件!$B$18)*前提条件!$B$10)*(1+前提条件!$B$19)*前提条件!$B$34+前提条件!$B$36/120+前提条件!$B$37/60)) -> 9977822.2 | C14: =12*(($A14*前提条件!$B$9*(C$4*前提条件!$B$13+前提条件!$B$14*2*前提条件!$B$15+前提条件!$B$16*前提条件!$B$17+前提条件!$B$18)*前提条件!$B$10)-(((前提条件!$B$21+MAX(前提条件!$B$24,CEILING($A14/前提条件!$B$23,0.5))*前提条件!$B$22)*(12+前提条件!$B$25)/12*(1+前提条件!$B$26)+前提条件!$B$27)+前提条件!$B$29+前提条件!$B$30+前提条件!$B$31+前提条件!$B$32+$A14*前提条件!$B$9*前提条件!$B$33+($A14*前提条件!$B$9*(C$4*前提条件!$B$13+前提条件!$B$14*2*前提条件!$B$15+前提条件!$B$16*前提条件!$B$17+前提条件!$B$18)*前提条件!$B$10)*(1+前提条件!$B$19)*前提条件!$B$34+前提条件!$B$36/120+前提条件!$B$37/60)) -> 11409992 | D14: =12*(($A14*前提条件!$B$9*(D$4*前提条件!$B$13+前提条件!$B$14*2*前提条件!$B$15+前提条件!$B$16*前提条件!$B$17+前提条件!$B$18)*前提条件!$B$10)-(((前提条件!$B$21+MAX(前提条件!$B$24,CEILING($A14/前提条件!$B$23,0.5))*前提条件!$B$22)*(12+前提条件!$B$25)/12*(1+前提条件!$B$26)+前提条件!$B$27)+前提条件!$B$29+前提条件!$B$30+前提条件!$B$31+前提条件!$B$32+$A14*前提条件!$B$9*前提条件!$B$33+($A14*前提条件!$B$9*(D$4*前提条件!$B$13+前提条件!$B$14*2*前提条件!$B$15+前提条件!$B$16*前提条件!$B$17+前提条件!$B$18)*前提条件!$B$10)*(1+前提条件!$B$19)*前提条件!$B$34+前提条件!$B$36/120+前提条件!$B$37/60)) -> 12507990 | E14: =12*(($A14*前提条件!$B$9*(E$4*前提条件!$B$13+前提条件!$B$14*2*前提条件!$B$15+前提条件!$B$16*前提条件!$B$17+前提条件!$B$18)*前提条件!$B$10)-(((前提条件!$B$21+MAX(前提条件!$B$24,CEILING($A14/前提条件!$B$23,0.5))*前提条件!$B$22)*(12+前提条件!$B$25)/12*(1+前提条件!$B$26)+前提条件!$B$27)+前提条件!$B$29+前提条件!$B$30+前提条件!$B$31+前提条件!$B$32+$A14*前提条件!$B$9*前提条件!$B$33+($A14*前提条件!$B$9*(E$4*前提条件!$B$13+前提条件!$B$14*2*前提条件!$B$15+前提条件!$B$16*前提条件!$B$17+前提条件!$B$18)*前提条件!$B$10)*(1+前提条件!$B$19)*前提条件!$B$34+前提条件!$B$36/120+前提条件!$B$37/60)) -> 13080858 | F14: =12*(($A14*前提条件!$B$9*(F$4*前提条件!$B$13+前提条件!$B$14*2*前提条件!$B$15+前提条件!$B$16*前提条件!$B$17+前提条件!$B$18)*前提条件!$B$10)-(((前提条件!$B$21+MAX(前提条件!$B$24,CEILING($A14/前提条件!$B$23,0.5))*前提条件!$B$22)*(12+前提条件!$B$25)/12*(1+前提条件!$B$26)+前提条件!$B$27)+前提条件!$B$29+前提条件!$B$30+前提条件!$B$31+前提条件!$B$32+$A14*前提条件!$B$9*前提条件!$B$33+($A14*前提条件!$B$9*(F$4*前提条件!$B$13+前提条件!$B$14*2*前提条件!$B$15+前提条件!$B$16*前提条件!$B$17+前提条件!$B$18)*前提条件!$B$10)*(1+前提条件!$B$19)*前提条件!$B$34+前提条件!$B$36/120+前提条件!$B$37/60)) -> 14035638
A15: 20 | B15: =12*(($A15*前提条件!$B$9*(B$4*前提条件!$B$13+前提条件!$B$14*2*前提条件!$B$15+前提条件!$B$16*前提条件!$B$17+前提条件!$B$18)*前提条件!$B$10)-(((前提条件!$B$21+MAX(前提条件!$B$24,CEILING($A15/前提条件!$B$23,0.5))*前提条件!$B$22)*(12+前提条件!$B$25)/12*(1+前提条件!$B$26)+前提条件!$B$27)+前提条件!$B$29+前提条件!$B$30+前提条件!$B$31+前提条件!$B$32+$A15*前提条件!$B$9*前提条件!$B$33+($A15*前提条件!$B$9*(B$4*前提条件!$B$13+前提条件!$B$14*2*前提条件!$B$15+前提条件!$B$16*前提条件!$B$17+前提条件!$B$18)*前提条件!$B$10)*(1+前提条件!$B$19)*前提条件!$B$34+前提条件!$B$36/120+前提条件!$B$37/60)) -> 11744681 | C15: =12*(($A15*前提条件!$B$9*(C$4*前提条件!$B$13+前提条件!$B$14*2*前提条件!$B$15+前提条件!$B$16*前提条件!$B$17+前提条件!$B$18)*前提条件!$B$10)-(((前提条件!$B$21+MAX(前提条件!$B$24,CEILING($A15/前提条件!$B$23,0.5))*前提条件!$B$22)*(12+前提条件!$B$25)/12*(1+前提条件!$B$26)+前提条件!$B$27)+前提条件!$B$29+前提条件!$B$30+前提条件!$B$31+前提条件!$B$32+$A15*前提条件!$B$9*前提条件!$B$33+($A15*前提条件!$B$9*(C$4*前提条件!$B$13+前提条件!$B$14*2*前提条件!$B$15+前提条件!$B$16*前提条件!$B$17+前提条件!$B$18)*前提条件!$B$10)*(1+前提条件!$B$19)*前提条件!$B$34+前提条件!$B$36/120+前提条件!$B$37/60)) -> 13252229 | D15: =12*(($A15*前提条件!$B$9*(D$4*前提条件!$B$13+前提条件!$B$14*2*前提条件!$B$15+前提条件!$B$16*前提条件!$B$17+前提条件!$B$18)*前提条件!$B$10)-(((前提条件!$B$21+MAX(前提条件!$B$24,CEILING($A15/前提条件!$B$23,0.5))*前提条件!$B$22)*(12+前提条件!$B$25)/12*(1+前提条件!$B$26)+前提条件!$B$27)+前提条件!$B$29+前提条件!$B$30+前提条件!$B$31+前提条件!$B$32+$A15*前提条件!$B$9*前提条件!$B$33+($A15*前提条件!$B$9*(D$4*前提条件!$B$13+前提条件!$B$14*2*前提条件!$B$15+前提条件!$B$16*前提条件!$B$17+前提条件!$B$18)*前提条件!$B$10)*(1+前提条件!$B$19)*前提条件!$B$34+前提条件!$B$36/120+前提条件!$B$37/60)) -> 14408015 | E15: =12*(($A15*前提条件!$B$9*(E$4*前提条件!$B$13+前提条件!$B$14*2*前提条件!$B$15+前提条件!$B$16*前提条件!$B$17+前提条件!$B$18)*前提条件!$B$10)-(((前提条件!$B$21+MAX(前提条件!$B$24,CEILING($A15/前提条件!$B$23,0.5))*前提条件!$B$22)*(12+前提条件!$B$25)/12*(1+前提条件!$B$26)+前提条件!$B$27)+前提条件!$B$29+前提条件!$B$30+前提条件!$B$31+前提条件!$B$32+$A15*前提条件!$B$9*前提条件!$B$33+($A15*前提条件!$B$9*(E$4*前提条件!$B$13+前提条件!$B$14*2*前提条件!$B$15+前提条件!$B$16*前提条件!$B$17+前提条件!$B$18)*前提条件!$B$10)*(1+前提条件!$B$19)*前提条件!$B$34+前提条件!$B$36/120+前提条件!$B$37/60)) -> 15011035 | F15: =12*(($A15*前提条件!$B$9*(F$4*前提条件!$B$13+前提条件!$B$14*2*前提条件!$B$15+前提条件!$B$16*前提条件!$B$17+前提条件!$B$18)*前提条件!$B$10)-(((前提条件!$B$21+MAX(前提条件!$B$24,CEILING($A15/前提条件!$B$23,0.5))*前提条件!$B$22)*(12+前提条件!$B$25)/12*(1+前提条件!$B$26)+前提条件!$B$27)+前提条件!$B$29+前提条件!$B$30+前提条件!$B$31+前提条件!$B$32+$A15*前提条件!$B$9*前提条件!$B$33+($A15*前提条件!$B$9*(F$4*前提条件!$B$13+前提条件!$B$14*2*前提条件!$B$15+前提条件!$B$16*前提条件!$B$17+前提条件!$B$18)*前提条件!$B$10)*(1+前提条件!$B$19)*前提条件!$B$34+前提条件!$B$36/120+前提条件!$B$37/60)) -> 16016066
A17: 読み方：赤＝赤字、緑＝黒字。処遇改善加算は同額を賃金に充てるため、損益には含めていません。

Sheet 開設ロードマップ
A1: 開設ロードマップ（2027年4月開設の場合）
A3: 時期 | B3: やること | C3: ポイント | D3: キャレオス内の連携先（クロスボーダー）
A4: 2026年10〜11月 | B4: 市場と制度の確認 | C4: 西条市・今治市の障がい福祉担当課へ事前相談。障害福祉計画のB型の見込量と、総量規制の有無を確認。地域区分・新規指定の算定区分も確認。 | D4: 第三管理部 事業開発課 地域共創係
A5: 2026年11〜12月 | B5: 利用ニーズの把握 | C5: 放デイ（日吉・西条）の中高生の人数と卒業時期、保護者アンケート。特別支援学校の進路担当・相談支援事業所へのヒアリング。 | D5: 第三管理部 マーケティング課 トータルサポート推進係、相談支援、放デイ各事業所
A6: 2026年12月 | B6: 法人内の事業計画・決裁 | C6: 本シミュレーションを実数に置き換え、投資額・回収計画を役員へ提示。 | D6: 第三管理部 事業開発課 地域共創係
A7: 2027年1月 | B7: 物件の確保 | C7: 送迎しやすい立地、作業スペース、用途・消防の適合を確認。 | D7: 第三管理部 事業開発課 地域共創係
A8: 2027年1〜2月 | B8: 生産活動（作業）の開拓 | C8: 地域企業の軽作業、農福連携（西条の農業）、飲食・製菓など、平均工賃を上げられる作業を確保。 | D8: 第三管理部 事業開発課 地域共創係、ラトリエトゥボナペティ ほか
A9: 2027年1〜3月 | B9: 人員の採用と育成 | C9: サービス管理責任者の要件（実務経験・研修）を確認。職業指導員・生活支援員を採用し、既存事業所で研修。 | D9: 生活介護、就労系事業所
A10: 2027年2月 | B10: 指定申請 | C10: 愛媛県へ指定申請（締切・事前協議の時期を確認）。 | D10: 第三管理部 事業開発課 地域共創係
A11: 2027年4月 | B11: 開設 | C11: 放デイ卒業生・特別支援学校卒業生の受け入れ。初年度は利用者の確保と工賃の底上げに集中。 | D11: 第三管理部 マーケティング課 トータルサポート推進係（利用者・保護者への周知）
A12: 2028年〜 | B12: 次の展開 | C12: 平均工賃の向上で報酬区分を上げる。放課後児童クラブ（委託）や相談支援との連携で、愛媛のトータルサポートの形をつくる。 | D12: 四国支社構想へ
