Workbook

Sheet 使い方
B2: 議事録テンプレート（Excel版）の使い方
B3: 「議事録」シートで1回分を記録し、ToDoだけを「アクション管理」シートに集めて進捗を追いかける構成です。
B5: シートの構成と使い分け
B6: シート名 | C6: 何をするシートか
B7: 議事録 | C7: 1回分の議事録。会議ごとにシートを右クリック →「移動またはコピー」→「コピーを作成する」で複製し、シート名を「0918_営業定例」などに変えて使います。
B8: アクション管理 | C8: 全会議のToDoを1か所に集めるシート。期限切れは自動で赤、期限3日前は黄色になります。フィルターで担当者ごとに絞り込めます。
B9: 会議ログ | C9: 開催した会議の一覧。ToDo件数と未完了件数はアクション管理シートから自動集計されます。
B10: 設定 | C10: ステータスの選択肢を管理するシート。言葉を変えたいときはここを編集します。
B12: 色の意味
B13: うすい黄色 | C13: 入力する欄です。ここだけ書き換えてください。
B14: グレー | C14: 数式が入っている自動計算欄です。上書きすると計算が壊れます。
B15: うすい緑 | C15: 記入例です。使い始めるときに行ごと削除してください。
B16: 赤（自動） | C16: アクション管理シートで期限を過ぎた未完了のToDoです。
B17: 黄（自動） | C17: アクション管理シートで期限まで3日以内のToDoです。
B19: ToDoの進捗（アクション管理シートから自動集計）
B20: 本日 | C20: =TODAY() -> 46283
B22: 件数 | C22: 未着手 | D22: 対応中 | E22: 完了 | F22: 期限超過
B23: 件 | C23: =COUNTIF(アクション管理!$G$2:$G$201,"未着手") -> 0 | D23: =COUNTIF(アクション管理!$G$2:$G$201,"対応中") -> 1 | E23: =COUNTIF(アクション管理!$G$2:$G$201,"完了") -> 0 | F23: =SUMPRODUCT((アクション管理!$D$2:$D$201<>"")*(アクション管理!$F$2:$F$201<>"")*(アクション管理!$F$2:$F$201<TODAY())*(アクション管理!$G$2:$G$201<>"完了")*(アクション管理!$G$2:$G$201<>"中止")) -> 0
B25: おすすめの進め方
B26: 会議前 | C26: 「議事録」シートをコピーし、会議名・日時・出席者とアジェンダ（2）を埋めておきます。ここまで準備できていると会議中の入力がぐっと楽になります。
B27: 会議中 | C27: 「3. 決定事項」と「4. アクションアイテム」だけをその場で埋めます。議論の詳細は後回しで構いません。
B28: 会議直後 | C28: 「4. アクションアイテム」の行をコピーして「アクション管理」シートに貼り付け、会議日と会議名を入れます。
B29: 会議後 | C29: 「5. 議事内容」を清書し、「会議ログ」シートに1行追加します。共有はPDF（ファイル → エクスポート → PDF）で。
B30: 次回まで | C30: 「アクション管理」シートを開き、赤くなっている行から着手します。完了したらステータスを「完了」に変えます。
B32: ※ 行が足りなくなったら、行番号を右クリック →「挿入」で増やせます。アクション管理シートは200行目まで数式と書式が入っています。

Sheet 議事録
B2: 議 事 録
B4: 会議名 | E4: 文書番号
B5: 開催日時 | E5: 開催場所
B6: 主催・議長 | E6: 書記（作成者）
B7: 出席者
B8: 欠席者
B9: 配布先
B11: 1. 会議の目的・ゴール（この会議で何が決まれば成功か）
B15: 2. アジェンダ（議題）
B16: No | C16: 議題 | D16: 担当 | E16: 予定時間 | F16: 資料
B17: 1
B18: 2
B19: 3
B20: 4
B22: 3. 決定事項（決まったことだけを書く）
B23: No | C23: 決定内容 | D23: 決定理由・背景 | F23: 決定者 | G23: 関連資料
B24: D-1
B25: D-2
B26: D-3
B27: D-4
B29: 4. アクションアイテム（誰が・何を・いつまでに）
B30: No | C30: 対応内容 | D30: 担当者 | E30: 期限 | F30: ステータス | G30: 備考
B31: A-1
B32: A-2
B33: A-3
B34: A-4
B35: A-5
B36: ※ 会議後、31〜35行目をコピーして「アクション管理」シートに貼り付けると進捗を追えます。
B38: 5. 議事内容（議論の要点と結論）
B39: 議題1
B40: 議論の要点
B42: 結論
B44: 議題2
B45: 議論の要点
... B54: 6. 保留・継続検討事項（決まらなかったこと）
B55: No | C55: 内容 | D55: 保留の理由 | F55: 再検討の時期 | G55: 担当
B56: P-1
B57: P-2
B58: P-3
B60: 7. 次回会議の予定
...

Sheet アクション管理
A1: 会議日 | B1: 会議名 | C1: No | D1: アクション内容 | E1: 担当者 | F1: 期限 | G1: ステータス | H1: 残日数 | I1: 完了日 | J1: 備考
A2: 46283 | B2: 営業定例 | C2: A-1 | D2: 新プランの価格案を3パターン作成する | E2: 山田 | F2: 46290 | G2: 対応中 | H2: =IF(OR($F2="",$G2="完了",$G2="中止"),"",$F2-TODAY()) -> 7 | J2: ←記入例です。行ごと削除して使ってください
H3: =IF(OR($F3="",$G3="完了",$G3="中止"),"",$F3-TODAY())
H4: =IF(OR($F4="",$G4="完了",$G4="中止"),"",$F4-TODAY())
H5: =IF(OR($F5="",$G5="完了",$G5="中止"),"",$F5-TODAY())
H6: =IF(OR($F6="",$G6="完了",$G6="中止"),"",$F6-TODAY())
H7: =IF(OR($F7="",$G7="完了",$G7="中止"),"",$F7-TODAY())
H8: =IF(OR($F8="",$G8="完了",$G8="中止"),"",$F8-TODAY())
H9: =IF(OR($F9="",$G9="完了",$G9="中止"),"",$F9-TODAY())
H10: =IF(OR($F10="",$G10="完了",$G10="中止"),"",$F10-TODAY())
H11: =IF(OR($F11="",$G11="完了",$G11="中止"),"",$F11-TODAY())
H12: =IF(OR($F12="",$G12="完了",$G12="中止"),"",$F12-TODAY())
H13: =IF(OR($F13="",$G13="完了",$G13="中止"),"",$F13-TODAY())
H14: =IF(OR($F14="",$G14="完了",$G14="中止"),"",$F14-TODAY())
... H201: =IF(OR($F201="",$G201="完了",$G201="中止"),"",$F201-TODAY())

Sheet 会議ログ
A1: 開催日 | B1: 会議名 | C1: 主催 | D1: 出席人数 | E1: 決定事項数 | F1: ToDo件数 | G1: 未完了 | H1: 議事録の保存先
A2: 46283 | B2: 営業定例 | C2: 田中 | D2: 6 | E2: 3 | F2: =IF($B2="","",COUNTIFS(アクション管理!$B$2:$B$201,$B2)) -> 1 | G2: =IF($B2="","",COUNTIFS(アクション管理!$B$2:$B$201,$B2)-COUNTIFS(アクション管理!$B$2:$B$201,$B2,アクション管理!$G$2:$G$201,"完了")-COUNTIFS(アクション管理!$B$2:$B$201,$B2,アクション管理!$G$2:$G$201,"中止")) -> 1 | H2: 20260918_営業定例_議事録.docx | I2: ←記入例です。行ごと削除して使ってください
F3: =IF($B3="","",COUNTIFS(アクション管理!$B$2:$B$201,$B3)) | G3: =IF($B3="","",COUNTIFS(アクション管理!$B$2:$B$201,$B3)-COUNTIFS(アクション管理!$B$2:$B$201,$B3,アクション管理!$G$2:$G$201,"完了")-COUNTIFS(アクション管理!$B$2:$B$201,$B3,アクション管理!$G$2:$G$201,"中止"))
F4: =IF($B4="","",COUNTIFS(アクション管理!$B$2:$B$201,$B4)) | G4: =IF($B4="","",COUNTIFS(アクション管理!$B$2:$B$201,$B4)-COUNTIFS(アクション管理!$B$2:$B$201,$B4,アクション管理!$G$2:$G$201,"完了")-COUNTIFS(アクション管理!$B$2:$B$201,$B4,アクション管理!$G$2:$G$201,"中止"))
F5: =IF($B5="","",COUNTIFS(アクション管理!$B$2:$B$201,$B5)) | G5: =IF($B5="","",COUNTIFS(アクション管理!$B$2:$B$201,$B5)-COUNTIFS(アクション管理!$B$2:$B$201,$B5,アクション管理!$G$2:$G$201,"完了")-COUNTIFS(アクション管理!$B$2:$B$201,$B5,アクション管理!$G$2:$G$201,"中止"))
F6: =IF($B6="","",COUNTIFS(アクション管理!$B$2:$B$201,$B6)) | G6: =IF($B6="","",COUNTIFS(アクション管理!$B$2:$B$201,$B6)-COUNTIFS(アクション管理!$B$2:$B$201,$B6,アクション管理!$G$2:$G$201,"完了")-COUNTIFS(アクション管理!$B$2:$B$201,$B6,アクション管理!$G$2:$G$201,"中止"))
F7: =IF($B7="","",COUNTIFS(アクション管理!$B$2:$B$201,$B7)) | G7: =IF($B7="","",COUNTIFS(アクション管理!$B$2:$B$201,$B7)-COUNTIFS(アクション管理!$B$2:$B$201,$B7,アクション管理!$G$2:$G$201,"完了")-COUNTIFS(アクション管理!$B$2:$B$201,$B7,アクション管理!$G$2:$G$201,"中止"))
F8: =IF($B8="","",COUNTIFS(アクション管理!$B$2:$B$201,$B8)) | G8: =IF($B8="","",COUNTIFS(アクション管理!$B$2:$B$201,$B8)-COUNTIFS(アクション管理!$B$2:$B$201,$B8,アクション管理!$G$2:$G$201,"完了")-COUNTIFS(アクション管理!$B$2:$B$201,$B8,アクション管理!$G$2:$G$201,"中止"))
F9: =IF($B9="","",COUNTIFS(アクション管理!$B$2:$B$201,$B9)) | G9: =IF($B9="","",COUNTIFS(アクション管理!$B$2:$B$201,$B9)-COUNTIFS(アクション管理!$B$2:$B$201,$B9,アクション管理!$G$2:$G$201,"完了")-COUNTIFS(アクション管理!$B$2:$B$201,$B9,アクション管理!$G$2:$G$201,"中止"))
F10: =IF($B10="","",COUNTIFS(アクション管理!$B$2:$B$201,$B10)) | G10: =IF($B10="","",COUNTIFS(アクション管理!$B$2:$B$201,$B10)-COUNTIFS(アクション管理!$B$2:$B$201,$B10,アクション管理!$G$2:$G$201,"完了")-COUNTIFS(アクション管理!$B$2:$B$201,$B10,アクション管理!$G$2:$G$201,"中止"))
F11: =IF($B11="","",COUNTIFS(アクション管理!$B$2:$B$201,$B11)) | G11: =IF($B11="","",COUNTIFS(アクション管理!$B$2:$B$201,$B11)-COUNTIFS(アクション管理!$B$2:$B$201,$B11,アクション管理!$G$2:$G$201,"完了")-COUNTIFS(アクション管理!$B$2:$B$201,$B11,アクション管理!$G$2:$G$201,"中止"))
F12: =IF($B12="","",COUNTIFS(アクション管理!$B$2:$B$201,$B12)) | G12: =IF($B12="","",COUNTIFS(アクション管理!$B$2:$B$201,$B12)-COUNTIFS(アクション管理!$B$2:$B$201,$B12,アクション管理!$G$2:$G$201,"完了")-COUNTIFS(アクション管理!$B$2:$B$201,$B12,アクション管理!$G$2:$G$201,"中止"))
F13: =IF($B13="","",COUNTIFS(アクション管理!$B$2:$B$201,$B13)) | G13: =IF($B13="","",COUNTIFS(アクション管理!$B$2:$B$201,$B13)-COUNTIFS(アクション管理!$B$2:$B$201,$B13,アクション管理!$G$2:$G$201,"完了")-COUNTIFS(アクション管理!$B$2:$B$201,$B13,アクション管理!$G$2:$G$201,"中止"))
F14: =IF($B14="","",COUNTIFS(アクション管理!$B$2:$B$201,$B14)) | G14: =IF($B14="","",COUNTIFS(アクション管理!$B$2:$B$201,$B14)-COUNTIFS(アクション管理!$B$2:$B$201,$B14,アクション管理!$G$2:$G$201,"完了")-COUNTIFS(アクション管理!$B$2:$B$201,$B14,アクション管理!$G$2:$G$201,"中止"))
... F101: =IF($B101="","",COUNTIFS(アクション管理!$B$2:$B$201,$B101)) | G101: =IF($B101="","",COUNTIFS(アクション管理!$B$2:$B$201,$B101)-COUNTIFS(アクション管理!$B$2:$B$201,$B101,アクション管理!$G$2:$G$201,"完了")-COUNTIFS(アクション管理!$B$2:$B$201,$B101,アクション管理!$G$2:$G$201,"中止"))

Sheet 設定
A1: ステータス | B1: メモ
A2: 未着手 | B2: まだ手をつけていない
A3: 対応中 | B3: 着手済み
A4: 完了 | B4: 完了（集計から除外されます）
A5: 保留 | B5: 事情があって止めている
A6: 中止 | B6: やらないことにした（集計から除外されます）
A8: ※ この5つが「議事録」「アクション管理」シートのプルダウンの選択肢です。
